Workbook

Sheet Summary
B1: Days in Month | C1: January | D1: February | E1: March | F1: April | G1: May | H1: June | I1: July | J1: Aug | K1: Sept | L1: Oct | M1: Nov | N1: Dec | O1: January | P1: February | Q1: March | R1: April | S1: May | T1: June | U1: July | V1: August | W1: Sept | X1: Oct | Y1: Nov | Z1: Dec
B2: Total | C2: =SUM(C3:C5) -> 31 | D2: =SUM(D3:D5) -> 28 | E2: =SUM(E3:E5) -> 31 | F2: =SUM(F3:F5) -> 30 | G2: =SUM(G3:G5) -> 31 | H2: =SUM(H3:H5) -> 30 | I2: =SUM(I3:I5) -> 31 | J2: =SUM(J3:J5) -> 31 | ... Z2: =SUM(Z3:Z5) -> 31
B3: M-F | C3: 23 | D3: 20 | E3: 21 | F3: 22 | G3: 22 | H3: 21 | I3: 23 | J3: 21 | K3: 22 | L3: 23 | M3: 20 | N3: 23 | O3: 22 | P3: 20 | Q3: 22 | R3: 22 | S3: 21 | T3: 22 | U3: 23 | V3: 21 | W3: 22 | X3: 22 | Y3: 21 | Z3: 23
B4: Sat | C4: 4 | D4: 4 | E4: 5 | F4: 4 | G4: 5 | H4: 4 | I4: 4 | J4: 5 | K4: 4 | L4: 4 | M4: 5 | N4: 4 | O4: 5 | P4: 4 | Q4: 4 | R4: 4 | S4: 5 | T4: 4 | U4: 4 | V4: 5 | W4: 4 | X4: 5 | Y4: 4 | Z4: 4
B5: Sun | C5: 4 | D5: 4 | E5: 5 | F5: 4 | G5: 4 | H5: 5 | I5: 4 | J5: 5 | K5: 4 | L5: 4 | M5: 5 | N5: 4 | O5: 4 | P5: 4 | Q5: 5 | R5: 4 | S5: 5 | T5: 4 | U5: 4 | V5: 5 | W5: 4 | X5: 4 | Y5: 5 | Z5: 4
B7: Business Days | C7: January | D7: February | E7: March | F7: April | G7: May | H7: June | I7: July | J7: Aug | K7: Sept | L7: Oct | M7: Nov | N7: Dec | O7: =+O1 -> January | P7: =+P1 -> February | Q7: =+Q1 -> March | R7: =+R1 -> April | S7: =+S1 -> May | T7: =+T1 -> June | U7: July | V7: August | W7: Sept | X7: Oct | Y7: Nov | Z7: Dec
B8: M-F | C8: 21 | D8: 20 | E8: 21 | F8: 21 | G8: 21 | H8: 21 | I8: 22 | J8: 21 | K8: 21 | L8: 23 | M8: 15 | N8: 19 | O8: =+O3-1 -> 21 | P8: =+P3 -> 20 | Q8: =+Q3 -> 22 | R8: =+R3 -> 22 | S8: =+S3-1 -> 20 | T8: =+T3 -> 22 | U8: =+U3-1 -> 22 | V8: =+V3 -> 21 | W8: =+W3-1 -> 21 | X8: =+X3 -> 22 | Y8: =+Y3-2 -> 19 | Z8: =+Z3-2 -> 21
B9: Sat | C9: 4 | D9: 4 | E9: 5 | F9: 4 | G9: 5 | H9: 4 | I9: 3 | J9: 4 | K9: 4 | L9: 4 | M9: 4 | N9: 3 | O9: =+O4 -> 5 | P9: =+P4 -> 4 | Q9: =+Q4 -> 4 | R9: =+R4 -> 4 | S9: =+S4 -> 5 | T9: =+T4 -> 4 | U9: =+U4 -> 4 | V9: =+V4 -> 5 | ... Z9: =+Z4 -> 4
B10: Sun | C10: 1 | D10: 1 | F10: 2 | G10: 2 | H10: 4
B11: Total | C11: =SUM(C8:C10) -> 26 | D11: =SUM(D8:D10) -> 25 | E11: =SUM(E8:E10) -> 26 | F11: =SUM(F8:F10) -> 27 | G11: =SUM(G8:G10) -> 28 | H11: =SUM(H8:H10) -> 29 | I11: =SUM(I8:I10) -> 25 | J11: =SUM(J8:J10) -> 25 | ... Z11: =SUM(Z8:Z10) -> 25
K12: 17
C13: =+'Fds Units'!B1 -> 45688 | D13: =+'Fds Units'!C1 -> 45716 | E13: =+'Fds Units'!D1 -> 45747 | F13: =+'Fds Units'!E1 -> 45777 | G13: =+'Fds Units'!F1 -> 45808 | H13: =EOMONTH(G13,1) -> 45838 | I13: =EOMONTH(H13,1) -> 45869 | J13: =EOMONTH(I13,1) -> 45900 | K13: =EOMONTH(J13,1) -> 45930 | L13: =EOMONTH(K13,1) -> 45961 | M13: =EOMONTH(L13,1) -> 45991 | N13: =EOMONTH(M13,1) -> 46022 | O13: =+'Fds Units'!U1 -> 46053 | P13: =+'Fds Units'!Y1 -> 46081 | Q13: =+'Fds Units'!AC1 -> 46112 | R13: =+'Fds Units'!AF1 -> 46142 | S13: =+'Fds Units'!AG1 -> 46173 | T13: =+'Fds Units'!AH1 -> 46203 | U13: =+'Fds Units'!AI1 -> 46234 | V13: =+'Fds Units'!AJ1 -> 46265 | W13: =+'Fds Units'!AK1 -> 46295 | X13: =+'Fds Units'!AL1 -> 46326 | Y13: =+'Fds Units'!AM1 -> 46356 | Z13: =+'Fds Units'!AN1 -> 46387
A14: Filler | C14: =+'Fds Units'!B2 -> Actuals | D14: =+'Fds Units'!C2 -> Actuals | E14: =+'Fds Units'!D2 -> Actuals | F14: =+'Fds Units'!E2 -> Actuals | G14: =+'Fds Units'!F2 -> Actuals | H14: =+'Fds Units'!G2 -> Actuals | I14: =+'Fds Units'!H2 -> Actuals | J14: =+'Fds Units'!I2 -> Actuals | K14: Actual | L14: =+'Fds Units'!N2 -> Schedule | M14: =+'Fds Units'!R2 -> Schedule | N14: Schedule | O14: Schedule | P14: Schedule | Q14: Forecast | R14: =+Q14 -> Forecast | S14: =+R14 -> Forecast | T14: =+S14 -> Forecast | U14: =+T14 -> Forecast | V14: =+U14 -> Forecast | W14: =+V14 -> Forecast | X14: =+W14 -> Forecast | Y14: =+X14 -> Forecast | Z14: =+Y14 -> Forecast
A15: Y4S/Y5 | B15: Volume | C15: =SUMIF('Fds Units'!$AP:$AP,Summary!$A15,'Fds Units'!B:B) -> 2060498 | D15: =SUMIF('Fds Units'!$AS:$AS,Summary!$A15,'Fds Units'!C:C) -> 1771466 | E15: =SUMIF('Fds Units'!$AV:$AV,Summary!$A15,'Fds Units'!D:D) -> 2067024 | F15: =SUMIF('Fds Units'!$AY:$AY,Summary!$A15,'Fds Units'!E:E) -> 691416 | G15: =SUMIF('Fds Units'!$BB:$BB,Summary!$A15,'Fds Units'!F:F) -> 2363343 | H15: =SUMIF('Fds Units'!$BE:$BE,Summary!$A15,'Fds Units'!G:G) -> 2520072 | I15: =SUMIF('Fds Units'!$BH:$BH,Summary!$A15,'Fds Units'!H:H) -> 1926173 | J15: =SUMIF('Fds Units'!$BK:$BK,Summary!$A15,'Fds Units'!I:I) -> 294432 | K15: =SUMIF('Fds Units'!$BN:$BN,Summary!$A15,'Fds Units'!J:J) -> 813718 | L15: =SUMIF('Fds Units'!$BQ:$BQ,Summary!$A15,'Fds Units'!K:K) -> 1301364 | M15: =SUMIF('Fds Units'!$BT:$BT,Summary!$A15,'Fds Units'!L:L)+SUMIF('Fds Units'!$BT:$BT,Summary!$A15,'Fds Units'!N:N) -> 2880696 | N15: =SUMIF('Fds Units'!$BW:$BW,Summary!$A15,'Fds Units'!R:R) -> 1121412 | O15: =SUMIF('Fds Units'!$BZ:$BZ,Summary!$A15,'Fds Units'!V:V) -> 49200 | P15: =SUMIF('Fds Units'!$CC:$CC,Summary!$A15,'Fds Units'!Z:Z) -> 1470024 | Q15: =SUMIF('Fds Units'!$CF:$CF,Summary!$A15,'Fds Units'!AC:AC) -> 705600 | R15: =SUMIF('Fds Units'!$CI:$CI,Summary!$A15,'Fds Units'!AF:AF) -> 324000 | S15: =SUMIF('Fds Units'!$CL:$CL,Summary!$A15,'Fds Units'!AG:AG) -> 1466028 | T15: =SUMIF('Fds Units'!$CO:$CO,Summary!$A15,'Fds Units'!AH:AH) -> 108000 | U15: =SUMIF('Fds Units'!$CR:$CR,Summary!$A15,'Fds Units'!AI:AI) -> 167536 | V15: =SUMIF('Fds Units'!$CU:$CU,Summary!$A15,'Fds Units'!AJ:AJ) -> 1053000 | W15: =SUMIF('Fds Units'!$CX:$CX,Summary!$A15,'Fds Units'!AK:AK) -> 300024 | X15: =SUMIF('Fds Units'!$DA:$DA,Summary!$A15,'Fds Units'!AL:AL) -> 936000 | Y15: =SUMIF('Fds Units'!$DD:$DD,Summary!$A15,'Fds Units'!AM:AM) -> 108000 | Z15: =SUMIF('Fds Units'!$DG:$DG,Summary!$A15,'Fds Units'!AN:AN) -> 261000
B16: Days | C16: =SUMIF('Fds Units'!$AP:$AP,Summary!$A15,'Fds Units'!DK:DK) -> 24 | D16: =SUMIF('Fds Units'!$AS:$AS,Summary!$A15,'Fds Units'!DL:DL) -> 24 | E16: =SUMIF('Fds Units'!$AV:$AV,Summary!$A15,'Fds Units'!DM:DM) -> 25 | F16: =SUMIF('Fds Units'!$AY:$AY,Summary!$A15,'Fds Units'!DN:DN) -> 22 | G16: =SUMIF('Fds Units'!$BB:$BB,Summary!$A15,'Fds Units'!DO:DO) -> 27 | H16: =SUMIF('Fds Units'!$BE:$BE,Summary!$A15,'Fds Units'!DP:DP) -> 27 | I16: =SUMIF('Fds Units'!$BH:$BH,Summary!$A15,'Fds Units'!DQ:DQ) -> 22 | J16: =SUMIF('Fds Units'!$BK:$BK,Summary!$A15,'Fds Units'!DR:DR) -> 4 | K16: =SUMIF('Fds Units'!$BN:$BN,Summary!$A15,'Fds Units'!DS:DS) -> 14 | L16: =SUMIF('Fds Units'!$BQ:$BQ,Summary!$A15,'Fds Units'!DT:DT) -> 25 | M16: =SUMIF('Fds Units'!$BT:$BT,Summary!$A15,'Fds Units'!DU:DU) -> 17 | N16: =SUMIF('Fds Units'!$BW:$BW,Summary!$A15,'Fds Units'!DV:DV) -> 12 | O16: =SUMIF('Fds Units'!$BZ:$BZ,Summary!$A15,'Fds Units'!DW:DW) -> 1 | P16: =SUMIF('Fds Units'!$CC:$CC,Summary!$A15,'Fds Units'!DX:DX) -> 17 | Q16: =SUMIF('Fds Units'!$CF:$CF,Summary!$A15,'Fds Units'!DY:DY) -> 9 | R16: =SUMIF('Fds Units'!$CI:$CI,Summary!$A15,'Fds Units'!DZ:DZ) -> 4 | S16: =SUMIF('Fds Units'!$CL:$CL,Summary!$A15,'Fds Units'!EA:EA) -> 18 | T16: =SUMIF('Fds Units'!$CO:$CO,Summary!$A15,'Fds Units'!EB:EB) -> 2 | U16: =SUMIF('Fds Units'!$CR:$CR,Summary!$A15,'Fds Units'!EC:EC) -> 2 | V16: =SUMIF('Fds Units'!$CU:$CU,Summary!$A15,'Fds Units'!ED:ED) -> 13 | W16: =SUMIF('Fds Units'!$CX:$CX,Summary!$A15,'Fds Units'!EE:EE) -> 4 | X16: =SUMIF('Fds Units'!$DA:$DA,Summary!$A15,'Fds Units'!EF:EF) -> 11 | Y16: =SUMIF('Fds Units'!$DD:$DD,Summary!$A15,'Fds Units'!EG:EG) -> 2 | Z16: =SUMIF('Fds Units'!$DG:$DG,Summary!$A15,'Fds Units'!EH:EH) -> 4
B17: Days Under/(Over) | C17: =+C$11-C16 -> 2 | D17: =+D$11-D16 -> 1 | E17: =+E$11-E16 -> 1 | F17: =+F$11-F16 -> 5 | G17: =+G$11-G16 -> 1 | H17: =+H$11-H16 -> 2 | I17: =+I$11-I16 -> 3 | J17: =+J$11-J16 -> 21 | ... N17: =+N$11-N16 -> 10 | O17: =+O$8-O16 -> 20 | P17: =+P$8-P16 -> 3 | Q17: =+Q$8-Q16 -> 13 | R17: =+R$8-R16 -> 18 | S17: =+S$8-S16 -> 2 | T17: =+T$8-T16 -> 20 | U17: =+U$8-U16 -> 20 | V17: =+V$8-V16 -> 8 | ... Z17: =+Z$8-Z16 -> 17
B18: Retort Cycles Req'd | C18: =SUMIF('Fds Units'!$AP:$AP,Summary!$A15,'Fds Units'!EJ:EJ) -> 152 | D18: =SUMIF('Fds Units'!$AS:$AS,Summary!$A15,'Fds Units'!EK:EK) -> 160 | E18: =SUMIF('Fds Units'!$AV:$AV,Summary!$A15,'Fds Units'!EL:EL) -> 136 | F18: =SUMIF('Fds Units'!$AY:$AY,Summary!$A15,'Fds Units'!EM:EM) -> 222 | G18: =SUMIF('Fds Units'!$BB:$BB,Summary!$A15,'Fds Units'!EN:EN) -> 136 | H18: =SUMIF('Fds Units'!$BE:$BE,Summary!$A15,'Fds Units'!EO:EO) -> 128 | I18: =SUMIF('Fds Units'!$BH:$BH,Summary!$A15,'Fds Units'!EP:EP) -> 138 | J18: =SUMIF('Fds Units'!$BK:$BK,Summary!$A15,'Fds Units'!EQ:EQ) -> 32 | K18: =SUMIF('Fds Units'!$BN:$BN,Summary!$A15,'Fds Units'!ER:ER) -> 119 | L18: =SUMIF('Fds Units'!$BQ:$BQ,Summary!$A15,'Fds Units'!ES:ES) -> 264 | M18: =SUMIF('Fds Units'!$BT:$BT,Summary!$A15,'Fds Units'!ET:ET) -> 177 | N18: =SUMIF('Fds Units'!$BW:$BW,Summary!$A15,'Fds Units'!EU:EU) -> 108 | O18: =SUMIF('Fds Units'!$BZ:$BZ,Summary!$A15,'Fds Units'!EV:EV) -> 10 | P18: =SUMIF('Fds Units'!$CC:$CC,Summary!$A15,'Fds Units'!EW:EW) -> 136 | Q18: =SUMIF('Fds Units'!$CF:$CF,Summary!$A15,'Fds Units'!EX:EX) -> 72 | R18: =SUMIF('Fds Units'!$CI:$CI,Summary!$A15,'Fds Units'!EY:EY) -> 32 | S18: =SUMIF('Fds Units'!$CL:$CL,Summary!$A15,'Fds Units'!EZ:EZ) -> 144 | T18: =SUMIF('Fds Units'!$CO:$CO,Summary!$A15,'Fds Units'!FA:FA) -> 16 | U18: =SUMIF('Fds Units'!$CR:$CR,Summary!$A15,'Fds Units'!FB:FB) -> 16 | V18: =SUMIF('Fds Units'!$CU:$CU,Summary!$A15,'Fds Units'!FC:FC) -> 104 | W18: =SUMIF('Fds Units'!$CX:$CX,Summary!$A15,'Fds Units'!FD:FD) -> 32 | X18: =SUMIF('Fds Units'!$DA:$DA,Summary!$A15,'Fds Units'!FE:FE) -> 88 | Y18: =SUMIF('Fds Units'!$DD:$DD,Summary!$A15,'Fds Units'!FF:FF) -> 16 | Z18: =SUMIF('Fds Units'!$DG:$DG,Summary!$A15,'Fds Units'!FG:FG) -> 32
C19: =+C15/C$74 -> 0.15361125 | D19: =+D15/D$74 -> 0.14775247 | E19: =+E15/E$74 -> 0.16055368 | F19: =+F15/F$74 -> 0.051500734 | G19: =+G15/G$74 -> 0.16896513 | H19: =+H15/H$74 -> 0.17956599 | I19: =+I15/I$74 -> 0.17086973 | J19: =+J15/J$74 -> 0.039134915 | ... Z19: =+Z15/Z$74 -> 0.032896224
A20: S6/S7 | B20: Volume | C20: =SUMIF('Fds Units'!$AP:$AP,Summary!$A20,'Fds Units'!B:B) -> 1374874 | D20: =SUMIF('Fds Units'!$AS:$AS,Summary!$A20,'Fds Units'!C:C) -> 558896 | E20: =SUMIF('Fds Units'!$AV:$AV,Summary!$A20,'Fds Units'!D:D) -> 2013402 | F20: =SUMIF('Fds Units'!$AY:$AY,Summary!$A20,'Fds Units'!E:E) -> 2389910 | G20: =SUMIF('Fds Units'!$BB:$BB,Summary!$A20,'Fds Units'!F:F) -> 2051490 | H20: =SUMIF('Fds Units'!$BE:$BE,Summary!$A20,'Fds Units'!G:G) -> 2042244 | I20: =SUMIF('Fds Units'!$BH:$BH,Summary!$A20,'Fds Units'!H:H) -> 2090352 | J20: =SUMIF('Fds Units'!$BK:$BK,Summary!$A20,'Fds Units'!I:I) -> 2187332 | K20: =SUMIF('Fds Units'!$BN:$BN,Summary!$A20,'Fds Units'!J:J) -> 1739870 | L20: =SUMIF('Fds Units'!$BQ:$BQ,Summary!$A20,'Fds Units'!K:K) -> 1863422 | M20: =SUMIF('Fds Units'!$BT:$BT,Summary!$A20,'Fds Units'!L:L)+SUMIF('Fds Units'!$BT:$BT,Summary!$A20,'Fds Units'!N:N) -> 4251644 | N20: =SUMIF('Fds Units'!$BW:$BW,Summary!$A20,'Fds Units'!R:R) -> 1773212 | O20: =SUMIF('Fds Units'!$BZ:$BZ,Summary!$A20,'Fds Units'!V:V) -> 1787000 | P20: =SUMIF('Fds Units'!$CC:$CC,Summary!$A20,'Fds Units'!Z:Z) -> 2206988 | Q20: =SUMIF('Fds Units'!$CF:$CF,Summary!$A20,'Fds Units'!AC:AC) -> 2802024 | R20: =SUMIF('Fds Units'!$CI:$CI,Summary!$A20,'Fds Units'!AF:AF) -> 2997012 | S20: =SUMIF('Fds Units'!$CL:$CL,Summary!$A20,'Fds Units'!AG:AG) -> 2576052 | T20: =SUMIF('Fds Units'!$CO:$CO,Summary!$A20,'Fds Units'!AH:AH) -> 2186004 | U20: =SUMIF('Fds Units'!$CR:$CR,Summary!$A20,'Fds Units'!AI:AI) -> 3105012 | V20: =SUMIF('Fds Units'!$CU:$CU,Summary!$A20,'Fds Units'!AJ:AJ) -> 2266008 | W20: =SUMIF('Fds Units'!$CX:$CX,Summary!$A20,'Fds Units'!AK:AK) -> 1797048 | X20: =SUMIF('Fds Units'!$DA:$DA,Summary!$A20,'Fds Units'!AL:AL) -> 2015004 | Y20: =SUMIF('Fds Units'!$DD:$DD,Summary!$A20,'Fds Units'!AM:AM) -> 2028048 | Z20: =SUMIF('Fds Units'!$DG:$DG,Summary!$A20,'Fds Units'!AN:AN) -> 942048
B21: Days | C21: =SUMIF('Fds Units'!$AP:$AP,Summary!$A20,'Fds Units'!DK:DK) -> 14 | D21: =SUMIF('Fds Units'!$AS:$AS,Summary!$A20,'Fds Units'!DL:DL) -> 10 | E21: =SUMIF('Fds Units'!$AV:$AV,Summary!$A20,'Fds Units'!DM:DM) -> 24 | F21: =SUMIF('Fds Units'!$AY:$AY,Summary!$A20,'Fds Units'!DN:DN) -> 26 | G21: =SUMIF('Fds Units'!$BB:$BB,Summary!$A20,'Fds Units'!DO:DO) -> 19 | H21: =SUMIF('Fds Units'!$BE:$BE,Summary!$A20,'Fds Units'!DP:DP) -> 25 | I21: =SUMIF('Fds Units'!$BH:$BH,Summary!$A20,'Fds Units'!DQ:DQ) -> 24 | J21: =SUMIF('Fds Units'!$BK:$BK,Summary!$A20,'Fds Units'!DR:DR) -> 22 | K21: =SUMIF('Fds Units'!$BN:$BN,Summary!$A20,'Fds Units'!DS:DS) -> 21 | L21: =SUMIF('Fds Units'!$BQ:$BQ,Summary!$A20,'Fds Units'!DT:DT) -> 25 | M21: =SUMIF('Fds Units'!$BT:$BT,Summary!$A20,'Fds Units'!DU:DU) -> 19 | N21: =SUMIF('Fds Units'!$BW:$BW,Summary!$A20,'Fds Units'!DV:DV) -> 16 | O21: =SUMIF('Fds Units'!$BZ:$BZ,Summary!$A20,'Fds Units'!DW:DW) -> 14 | P21: =SUMIF('Fds Units'!$CC:$CC,Summary!$A20,'Fds Units'!DX:DX) -> 16 | Q21: =SUMIF('Fds Units'!$CF:$CF,Summary!$A20,'Fds Units'!DY:DY) -> 20 | R21: =SUMIF('Fds Units'!$CI:$CI,Summary!$A20,'Fds Units'!DZ:DZ) -> 22 | S21: =SUMIF('Fds Units'!$CL:$CL,Summary!$A20,'Fds Units'!EA:EA) -> 19 | T21: =SUMIF('Fds Units'!$CO:$CO,Summary!$A20,'Fds Units'!EB:EB) -> 16 | U21: =SUMIF('Fds Units'!$CR:$CR,Summary!$A20,'Fds Units'!EC:EC) -> 22 | V21: =SUMIF('Fds Units'!$CU:$CU,Summary!$A20,'Fds Units'!ED:ED) -> 17 | W21: =SUMIF('Fds Units'!$CX:$CX,Summary!$A20,'Fds Units'!EE:EE) -> 13 | X21: =SUMIF('Fds Units'!$DA:$DA,Summary!$A20,'Fds Units'!EF:EF) -> 15 | Y21: =SUMIF('Fds Units'!$DD:$DD,Summary!$A20,'Fds Units'!EG:EG) -> 14 | Z21: =SUMIF('Fds Units'!$DG:$DG,Summary!$A20,'Fds Units'!EH:EH) -> 7
B22: Days Under/(Over) | C22: =+C$11-C21 -> 12 | D22: =+D$11-D21 -> 15 | E22: =+E$11-E21 -> 2 | F22: =+F$11-F21 -> 1 | G22: =+G$11-G21 -> 9 | H22: =+H$11-H21 -> 4 | I22: =+I$11-I21 -> 1 | J22: =+J$11-J21 -> 3 | ... N22: =+N$11-N21 -> 6 | O22: =+O$8-O21 -> 7 | P22: =+P$8-P21 -> 4 | Q22: =+Q$8-Q21 -> 2 | R22: =+R$8-R21 -> 0 | S22: =+S$8-S21 -> 1 | T22: =+T$8-T21 -> 6 | U22: =+U$8-U21 -> 0 | V22: =+V$8-V21 -> 4 | ... Z22: =+Z$8-Z21 -> 14
B23: Retort Cycles Req'd | C23: =SUMIF('Fds Units'!$AP:$AP,Summary!$A20,'Fds Units'!EJ:EJ) -> 44 | D23: =SUMIF('Fds Units'!$AS:$AS,Summary!$A20,'Fds Units'!EK:EK) -> 40 | E23: =SUMIF('Fds Units'!$AV:$AV,Summary!$A20,'Fds Units'!EL:EL) -> 48 | F23: =SUMIF('Fds Units'!$AY:$AY,Summary!$A20,'Fds Units'!EM:EM) -> 104 | G23: =SUMIF('Fds Units'!$BB:$BB,Summary!$A20,'Fds Units'!EN:EN) -> 74 | H23: =SUMIF('Fds Units'!$BE:$BE,Summary!$A20,'Fds Units'!EO:EO) -> 66 | I23: =SUMIF('Fds Units'!$BH:$BH,Summary!$A20,'Fds Units'!EP:EP) -> 96 | J23: =SUMIF('Fds Units'!$BK:$BK,Summary!$A20,'Fds Units'!EQ:EQ) -> 88 | K23: =SUMIF('Fds Units'!$BN:$BN,Summary!$A20,'Fds Units'!ER:ER) -> 84 | L23: =SUMIF('Fds Units'!$BQ:$BQ,Summary!$A20,'Fds Units'!ES:ES) -> 100 | M23: =SUMIF('Fds Units'!$BT:$BT,Summary!$A20,'Fds Units'!ET:ET) -> 76 | N23: =SUMIF('Fds Units'!$BW:$BW,Summary!$A20,'Fds Units'!EU:EU) -> 64 | O23: =SUMIF('Fds Units'!$BZ:$BZ,Summary!$A20,'Fds Units'!EV:EV) -> 56 | P23: =SUMIF('Fds Units'!$CC:$CC,Summary!$A20,'Fds Units'!EW:EW) -> 64 | Q23: =SUMIF('Fds Units'!$CF:$CF,Summary!$A20,'Fds Units'!EX:EX) -> 80 | R23: =SUMIF('Fds Units'!$CI:$CI,Summary!$A20,'Fds Units'!EY:EY) -> 88 | S23: =SUMIF('Fds Units'!$CL:$CL,Summary!$A20,'Fds Units'!EZ:EZ) -> 76 | T23: =SUMIF('Fds Units'!$CO:$CO,Summary!$A20,'Fds Units'!FA:FA) -> 64 | U23: =SUMIF('Fds Units'!$CR:$CR,Summary!$A20,'Fds Units'!FB:FB) -> 88 | V23: =SUMIF('Fds Units'!$CU:$CU,Summary!$A20,'Fds Units'!FC:FC) -> 68 | W23: =SUMIF('Fds Units'!$CX:$CX,Summary!$A20,'Fds Units'!FD:FD) -> 52 | X23: =SUMIF('Fds Units'!$DA:$DA,Summary!$A20,'Fds Units'!FE:FE) -> 60 | Y23: =SUMIF('Fds Units'!$DD:$DD,Summary!$A20,'Fds Units'!FF:FF) -> 56 | Z23: =SUMIF('Fds Units'!$DG:$DG,Summary!$A20,'Fds Units'!FG:FG) -> 28
C24: =+C20/C$74 -> 0.10249761 | D24: =+D20/D$74 -> 0.046615778 | E24: =+E20/E$74 -> 0.15638866 | F24: =+F20/F$74 -> 0.17801457 | G24: =+G20/G$74 -> 0.14666947 | H24: =+H20/H$74 -> 0.14551868 | I24: =+I20/I$74 -> 0.18543396 | J24: =+J20/J$74 -> 0.29073284 | ... Z24: =+Z20/Z$74 -> 0.11873495
A25: W2 | B25: Volume | C25: =SUMIF('Fds Units'!$AP:$AP,Summary!$A25,'Fds Units'!B:B) -> 4598995 | D25: =SUMIF('Fds Units'!$AS:$AS,Summary!$A25,'Fds Units'!C:C) -> 4451256 | E25: =SUMIF('Fds Units'!$AV:$AV,Summary!$A25,'Fds Units'!D:D) -> 3854244 | F25: =SUMIF('Fds Units'!$AY:$AY,Summary!$A25,'Fds Units'!E:E)-F40 -> 5576652 | G25: =SUMIF('Fds Units'!$BB:$BB,Summary!$A25,'Fds Units'!F:F) -> 4010496 | H25: =SUMIF('Fds Units'!$BE:$BE,Summary!$A25,'Fds Units'!G:G) -> 4240032 | I25: =SUMIF('Fds Units'!$BH:$BH,Summary!$A25,'Fds Units'!H:H) -> 4180995 | J25: =SUMIF('Fds Units'!$BK:$BK,Summary!$A25,'Fds Units'!I:I) -> 3224871 | K25: =SUMIF('Fds Units'!$BN:$BN,Summary!$A25,'Fds Units'!J:J) -> 3687920 | L25: =SUMIF('Fds Units'!$BQ:$BQ,Summary!$A25,'Fds Units'!K:K) -> 4136574 | M25: =SUMIF('Fds Units'!$BT:$BT,Summary!$A25,'Fds Units'!L:L)+SUMIF('Fds Units'!$BT:$BT,Summary!$A25,'Fds Units'!N:N) -> 5381544 | N25: =SUMIF('Fds Units'!$BW:$BW,Summary!$A25,'Fds Units'!R:R) -> 2944080 | O25: =SUMIF('Fds Units'!$BZ:$BZ,Summary!$A25,'Fds Units'!V:V) -> 3906360 | P25: =SUMIF('Fds Units'!$CC:$CC,Summary!$A25,'Fds Units'!Z:Z) -> 4344468 | Q25: =SUMIF('Fds Units'!$CF:$CF,Summary!$A25,'Fds Units'!AC:AC) -> 4907948 | R25: =SUMIF('Fds Units'!$CI:$CI,Summary!$A25,'Fds Units'!AF:AF) -> 9064104 | S25: =SUMIF('Fds Units'!$CL:$CL,Summary!$A25,'Fds Units'!AG:AG) -> 5700000 | T25: =SUMIF('Fds Units'!$CO:$CO,Summary!$A25,'Fds Units'!AH:AH) -> 3249138.8 | U25: =SUMIF('Fds Units'!$CR:$CR,Summary!$A25,'Fds Units'!AI:AI) -> 3274134.8 | V25: =SUMIF('Fds Units'!$CU:$CU,Summary!$A25,'Fds Units'!AJ:AJ) -> 2961621 | W25: =SUMIF('Fds Units'!$CX:$CX,Summary!$A25,'Fds Units'!AK:AK) -> 2961622.5 | X25: =SUMIF('Fds Units'!$DA:$DA,Summary!$A25,'Fds Units'!AL:AL) -> 3836626.5 | Y25: =SUMIF('Fds Units'!$DD:$DD,Summary!$A25,'Fds Units'!AM:AM) -> 2736622.5 | Z25: =SUMIF('Fds Units'!$DG:$DG,Summary!$A25,'Fds Units'!AN:AN) -> 2761618.5
B26: Days | C26: =SUMIF('Fds Units'!$AP:$AP,Summary!$A25,'Fds Units'!DK:DK) -> 26 | D26: =SUMIF('Fds Units'!$AS:$AS,Summary!$A25,'Fds Units'!DL:DL) -> 23 | E26: =SUMIF('Fds Units'!$AV:$AV,Summary!$A25,'Fds Units'!DM:DM) -> 26 | F26: =SUMIF('Fds Units'!$AY:$AY,Summary!$A25,'Fds Units'!DN:DN) -> 25 | G26: =SUMIF('Fds Units'!$BB:$BB,Summary!$A25,'Fds Units'!DO:DO) -> 25 | H26: =SUMIF('Fds Units'!$BE:$BE,Summary!$A25,'Fds Units'!DP:DP) -> 25 | I26: =SUMIF('Fds Units'!$BH:$BH,Summary!$A25,'Fds Units'!DQ:DQ) -> 25 | J26: =SUMIF('Fds Units'!$BK:$BK,Summary!$A25,'Fds Units'!DR:DR) -> 25 | K26: =SUMIF('Fds Units'!$BN:$BN,Summary!$A25,'Fds Units'!DS:DS) -> 25 | L26: =SUMIF('Fds Units'!$BQ:$BQ,Summary!$A25,'Fds Units'!DT:DT) -> 26 | M26: =SUMIF('Fds Units'!$BT:$BT,Summary!$A25,'Fds Units'!DU:DU) -> 18 | N26: =SUMIF('Fds Units'!$BW:$BW,Summary!$A25,'Fds Units'!DV:DV) -> 18 | O26: =SUMIF('Fds Units'!$BZ:$BZ,Summary!$A25,'Fds Units'!DW:DW) -> 24 | P26: =SUMIF('Fds Units'!$CC:$CC,Summary!$A25,'Fds Units'!DX:DX) -> 17 | Q26: =SUMIF('Fds Units'!$CF:$CF,Summary!$A25,'Fds Units'!DY:DY) -> 28 | R26: =SUMIF('Fds Units'!$CI:$CI,Summary!$A25,'Fds Units'!DZ:DZ) -> 53 | S26: =SUMIF('Fds Units'!$CL:$CL,Summary!$A25,'Fds Units'!EA:EA) -> 27 | T26: =SUMIF('Fds Units'!$CO:$CO,Summary!$A25,'Fds Units'!EB:EB) -> 20 | U26: =SUMIF('Fds Units'!$CR:$CR,Summary!$A25,'Fds Units'!EC:EC) -> 21 | V26: =SUMIF('Fds Units'!$CU:$CU,Summary!$A25,'Fds Units'!ED:ED) -> 19 | W26: =SUMIF('Fds Units'!$CX:$CX,Summary!$A25,'Fds Units'!EE:EE) -> 19 | X26: =SUMIF('Fds Units'!$DA:$DA,Summary!$A25,'Fds Units'!EF:EF) -> 24 | Y26: =SUMIF('Fds Units'!$DD:$DD,Summary!$A25,'Fds Units'!EG:EG) -> 18 | Z26: =SUMIF('Fds Units'!$DG:$DG,Summary!$A25,'Fds Units'!EH:EH) -> 11
B27: Days Under/(Over) | C27: =+C$11-C26 -> 0 | D27: =+D$11-D26-D10 -> 1 | E27: =+E$11-E26-E10 -> 0 | F27: =+F$11-F26-F10 -> 0 | G27: =+G$11-G26-G10 -> 1 | H27: =+H$11-H26-H10 -> 0 | I27: =+I$11-I26-I10 -> 0 | J27: =+J$11-J26-J10 -> 0 | K27: =+K$11-K26 -> 0 | L27: =+L$11-L26 -> 1 | M27: =+M$11-M26 -> 1 | N27: =+N$11-N26 -> 4 | O27: =+O$11-O26 -> 2 | P27: =+P$11-P26 -> 7 | Q27: =+Q$11-Q26 -> -2 | R27: =+R$11-R26 -> -27 | ... Z27: =+Z$11-Z26 -> 14
B28: Retort Cycles Req'd | C28: =SUMIF('Fds Units'!$AP:$AP,Summary!$A25,'Fds Units'!EJ:EJ) -> 182 | D28: =SUMIF('Fds Units'!$AS:$AS,Summary!$A25,'Fds Units'!EK:EK) -> 161 | E28: =SUMIF('Fds Units'!$AV:$AV,Summary!$A25,'Fds Units'!EL:EL) -> 206 | F28: =SUMIF('Fds Units'!$AY:$AY,Summary!$A25,'Fds Units'!EM:EM) -> 175 | G28: =SUMIF('Fds Units'!$BB:$BB,Summary!$A25,'Fds Units'!EN:EN) -> 172 | H28: =SUMIF('Fds Units'!$BE:$BE,Summary!$A25,'Fds Units'!EO:EO) -> 175 | I28: =SUMIF('Fds Units'!$BH:$BH,Summary!$A25,'Fds Units'!EP:EP) -> 175 | J28: =SUMIF('Fds Units'!$BK:$BK,Summary!$A25,'Fds Units'!EQ:EQ) -> 187 | K28: =SUMIF('Fds Units'!$BN:$BN,Summary!$A25,'Fds Units'!ER:ER) -> 175 | L28: =SUMIF('Fds Units'!$BQ:$BQ,Summary!$A25,'Fds Units'!ES:ES) -> 182 | M28: =SUMIF('Fds Units'!$BT:$BT,Summary!$A25,'Fds Units'!ET:ET) -> 126 | N28: =SUMIF('Fds Units'!$BW:$BW,Summary!$A25,'Fds Units'!EU:EU) -> 130 | O28: =SUMIF('Fds Units'!$BZ:$BZ,Summary!$A25,'Fds Units'!EV:EV) -> 168 | P28: =SUMIF('Fds Units'!$CC:$CC,Summary!$A25,'Fds Units'!EW:EW) -> 119 | Q28: =SUMIF('Fds Units'!$CF:$CF,Summary!$A25,'Fds Units'!EX:EX) -> 196 | R28: =SUMIF('Fds Units'!$CI:$CI,Summary!$A25,'Fds Units'!EY:EY) -> 371 | S28: =SUMIF('Fds Units'!$CL:$CL,Summary!$A25,'Fds Units'!EZ:EZ) -> 189 | T28: =SUMIF('Fds Units'!$CO:$CO,Summary!$A25,'Fds Units'!FA:FA) -> 140 | U28: =SUMIF('Fds Units'!$CR:$CR,Summary!$A25,'Fds Units'!FB:FB) -> 147 | V28: =SUMIF('Fds Units'!$CU:$CU,Summary!$A25,'Fds Units'!FC:FC) -> 133 | W28: =SUMIF('Fds Units'!$CX:$CX,Summary!$A25,'Fds Units'!FD:FD) -> 133 | X28: =SUMIF('Fds Units'!$DA:$DA,Summary!$A25,'Fds Units'!FE:FE) -> 168 | Y28: =SUMIF('Fds Units'!$DD:$DD,Summary!$A25,'Fds Units'!FF:FF) -> 126 | Z28: =SUMIF('Fds Units'!$DG:$DG,Summary!$A25,'Fds Units'!FG:FG) -> 77
C29: =+C25/C$74 -> 0.34285759 | D29: =+D25/D$74 -> 0.37126543 | E29: =+E25/E$74 -> 0.29937392 | F29: =+F25/F$74 -> 0.41538187 | G29: =+G25/G$74 -> 0.28672689 | H29: =+H25/H$74 -> 0.30212055 | I29: =+I25/I$74 -> 0.37089374 | J29: =+J25/J$74 -> 0.42863905 | ... Z29: =+Z25/Z$74 -> 0.34807211
A30: W3 | B30: Volume | M30: =SUMIF('Fds Units'!$BT:$BT,Summary!$A30,'Fds Units'!L:L)+SUMIF('Fds Units'!$BT:$BT,Summary!$A30,'Fds Units'!N:N) -> 199968 | N30: =SUMIF('Fds Units'!$BW:$BW,Summary!$A30,'Fds Units'!R:R) -> 2378412 | O30: =SUMIF('Fds Units'!$BZ:$BZ,Summary!$A30,'Fds Units'!V:V) -> 3923508 | P30: =SUMIF('Fds Units'!$CC:$CC,Summary!$A30,'Fds Units'!Z:Z) -> 4927080 | Q30: =SUMIF('Fds Units'!$CF:$CF,Summary!$A30,'Fds Units'!AC:AC) -> 3245996 | R30: =SUMIF('Fds Units'!$CI:$CI,Summary!$A30,'Fds Units'!AF:AF) -> 5039472 | S30: =SUMIF('Fds Units'!$CL:$CL,Summary!$A30,'Fds Units'!AG:AG) -> 10104000 | T30: =SUMIF('Fds Units'!$CO:$CO,Summary!$A30,'Fds Units'!AH:AH) -> 3253441.8 | U30: =SUMIF('Fds Units'!$CR:$CR,Summary!$A30,'Fds Units'!AI:AI) -> 3457441.8 | V30: =SUMIF('Fds Units'!$CU:$CU,Summary!$A30,'Fds Units'!AJ:AJ) -> 3457441.8 | W30: =SUMIF('Fds Units'!$CX:$CX,Summary!$A30,'Fds Units'!AK:AK) -> 3445441.8 | X30: =SUMIF('Fds Units'!$DA:$DA,Summary!$A30,'Fds Units'!AL:AL) -> 3603841.8 | Y30: =SUMIF('Fds Units'!$DD:$DD,Summary!$A30,'Fds Units'!AM:AM) -> 3551041.8 | Z30: =SUMIF('Fds Units'!$DG:$DG,Summary!$A30,'Fds Units'!AN:AN) -> 3551041.8
B31: Days | M31: =SUMIF('Fds Units'!$BT:$BT,Summary!$A30,'Fds Units'!DU:DU) -> 3 | N31: =SUMIF('Fds Units'!$BW:$BW,Summary!$A30,'Fds Units'!DV:DV) -> 19 | O31: =SUMIF('Fds Units'!$BZ:$BZ,Summary!$A30,'Fds Units'!DW:DW) -> 30 | P31: =SUMIF('Fds Units'!$CC:$CC,Summary!$A30,'Fds Units'!DX:DX) -> 33 | Q31: =SUMIF('Fds Units'!$CF:$CF,Summary!$A30,'Fds Units'!DY:DY) -> 40 | R31: =SUMIF('Fds Units'!$CI:$CI,Summary!$A30,'Fds Units'!DZ:DZ) -> 55 | S31: =SUMIF('Fds Units'!$CL:$CL,Summary!$A30,'Fds Units'!EA:EA) -> 55 | T31: =SUMIF('Fds Units'!$CO:$CO,Summary!$A30,'Fds Units'!EB:EB) -> 26 | U31: =SUMIF('Fds Units'!$CR:$CR,Summary!$A30,'Fds Units'!EC:EC) -> 27 | V31: =SUMIF('Fds Units'!$CU:$CU,Summary!$A30,'Fds Units'!ED:ED) -> 27 | W31: =SUMIF('Fds Units'!$CX:$CX,Summary!$A30,'Fds Units'!EE:EE) -> 27 | X31: =SUMIF('Fds Units'!$DA:$DA,Summary!$A30,'Fds Units'!EF:EF) -> 29 | Y31: =SUMIF('Fds Units'!$DD:$DD,Summary!$A30,'Fds Units'!EG:EG) -> 29 | Z31: =SUMIF('Fds Units'!$DG:$DG,Summary!$A30,'Fds Units'!EH:EH) -> 12
B32: Days Under/(Over) | M32: =+M$11-M31 -> 16 | N32: =+N$11-N31 -> 3 | O32: =+O$11-O31 -> -4 | P32: =+P$11-P31 -> -9 | Q32: =+Q$11-Q31 -> -14 | R32: =+R$11-R31 -> -29 | S32: =+S$11-S31 -> -30 | T32: =+T$11-T31 -> 0 | ... Z32: =+Z$11-Z31 -> 13
B33: Retort Cycles Req'd | M33: =SUMIF('Fds Units'!$BT:$BT,Summary!$A30,'Fds Units'!ET:ET) -> 27 | N33: =SUMIF('Fds Units'!$BW:$BW,Summary!$A30,'Fds Units'!EU:EU) -> 173 | O33: =SUMIF('Fds Units'!$BZ:$BZ,Summary!$A30,'Fds Units'!EV:EV) -> 360 | P33: =SUMIF('Fds Units'!$CC:$CC,Summary!$A30,'Fds Units'!EW:EW) -> 307 | Q33: =SUMIF('Fds Units'!$CF:$CF,Summary!$A30,'Fds Units'!EX:EX) -> 375 | R33: =SUMIF('Fds Units'!$CI:$CI,Summary!$A30,'Fds Units'!EY:EY) -> 594 | S33: =SUMIF('Fds Units'!$CL:$CL,Summary!$A30,'Fds Units'!EZ:EZ) -> 659 | T33: =SUMIF('Fds Units'!$CO:$CO,Summary!$A30,'Fds Units'!FA:FA) -> 345 | U33: =SUMIF('Fds Units'!$CR:$CR,Summary!$A30,'Fds Units'!FB:FB) -> 347 | V33: =SUMIF('Fds Units'!$CU:$CU,Summary!$A30,'Fds Units'!FC:FC) -> 347 | W33: =SUMIF('Fds Units'!$CX:$CX,Summary!$A30,'Fds Units'!FD:FD) -> 347 | X33: =SUMIF('Fds Units'!$DA:$DA,Summary!$A30,'Fds Units'!FE:FE) -> 372 | Y33: =SUMIF('Fds Units'!$DD:$DD,Summary!$A30,'Fds Units'!FF:FF) -> 372 | Z33: =SUMIF('Fds Units'!$DG:$DG,Summary!$A30,'Fds Units'!FG:FG) -> 166
C34: =+C30/C$74 -> 0 | D34: =+D30/D$74 -> 0 | E34: =+E30/E$74 -> 0 | F34: =+F30/F$74 -> 0 | G34: =+G30/G$74 -> 0 | H34: =+H30/H$74 -> 0 | I34: =+I30/I$74 -> 0 | J34: =+J30/J$74 -> 0 | ... Z34: =+Z30/Z$74 -> 0.44757037
A35: Y3NS | B35: Volume | C35: =SUMIF('Fds Units'!$AP:$AP,Summary!$A35,'Fds Units'!B:B) -> 2380269 | D35: =SUMIF('Fds Units'!$AS:$AS,Summary!$A35,'Fds Units'!C:C) -> 2350932 | E35: =SUMIF('Fds Units'!$AV:$AV,Summary!$A35,'Fds Units'!D:D) -> 2298792 | F35: =SUMIF('Fds Units'!$AY:$AY,Summary!$A35,'Fds Units'!E:E) -> 2714266 | G35: =SUMIF('Fds Units'!$BB:$BB,Summary!$A35,'Fds Units'!F:F) -> 2851011 | H35: =SUMIF('Fds Units'!$BE:$BE,Summary!$A35,'Fds Units'!G:G) -> 2942615 | I35: =SUMIF('Fds Units'!$BH:$BH,Summary!$A35,'Fds Units'!H:H) -> 2354363 | J35: =SUMIF('Fds Units'!$BK:$BK,Summary!$A35,'Fds Units'!I:I) -> 1561917 | K35: =SUMIF('Fds Units'!$BN:$BN,Summary!$A35,'Fds Units'!J:J) -> 1320450 | L35: =SUMIF('Fds Units'!$BQ:$BQ,Summary!$A35,'Fds Units'!K:K) -> 2663796 | M35: =SUMIF('Fds Units'!$BT:$BT,Summary!$A35,'Fds Units'!L:L)+SUMIF('Fds Units'!$BT:$BT,Summary!$A35,'Fds Units'!N:N) -> 3985941 | N35: =SUMIF('Fds Units'!$BW:$BW,Summary!$A35,'Fds Units'!R:R) -> 2206000 | O35: =SUMIF('Fds Units'!$BZ:$BZ,Summary!$A35,'Fds Units'!V:V) -> 2860000 | P35: =SUMIF('Fds Units'!$CC:$CC,Summary!$A35,'Fds Units'!Z:Z) -> 2237000 | Q35: =SUMIF('Fds Units'!$CF:$CF,Summary!$A35,'Fds Units'!AC:AC) -> 1630000 | R35: =SUMIF('Fds Units'!$CI:$CI,Summary!$A35,'Fds Units'!AF:AF) -> 1735000 | S35: =SUMIF('Fds Units'!$CL:$CL,Summary!$A35,'Fds Units'!AG:AG) -> 1430000 | T35: =SUMIF('Fds Units'!$CO:$CO,Summary!$A35,'Fds Units'!AH:AH) -> 820000 | U35: =SUMIF('Fds Units'!$CR:$CR,Summary!$A35,'Fds Units'!AI:AI) -> 1155000 | V35: =SUMIF('Fds Units'!$CU:$CU,Summary!$A35,'Fds Units'!AJ:AJ) -> 715000 | W35: =SUMIF('Fds Units'!$CX:$CX,Summary!$A35,'Fds Units'!AK:AK) -> 1135000 | X35: =SUMIF('Fds Units'!$DA:$DA,Summary!$A35,'Fds Units'!AL:AL) -> 905000 | Y35: =SUMIF('Fds Units'!$DD:$DD,Summary!$A35,'Fds Units'!AM:AM) -> 1125000 | Z35: =SUMIF('Fds Units'!$DG:$DG,Summary!$A35,'Fds Units'!AN:AN) -> 400000
B36: Days | C36: =SUMIF('Fds Units'!$AP:$AP,Summary!$A35,'Fds Units'!DK:DK) -> 26 | D36: =SUMIF('Fds Units'!$AS:$AS,Summary!$A35,'Fds Units'!DL:DL) -> 25 | E36: =SUMIF('Fds Units'!$AV:$AV,Summary!$A35,'Fds Units'!DM:DM) -> 26 | F36: =SUMIF('Fds Units'!$AY:$AY,Summary!$A35,'Fds Units'!DN:DN) -> 29 | G36: =SUMIF('Fds Units'!$BB:$BB,Summary!$A35,'Fds Units'!DO:DO) -> 28 | H36: =SUMIF('Fds Units'!$BE:$BE,Summary!$A35,'Fds Units'!DP:DP) -> 29 | I36: =SUMIF('Fds Units'!$BH:$BH,Summary!$A35,'Fds Units'!DQ:DQ) -> 25 | J36: =SUMIF('Fds Units'!$BK:$BK,Summary!$A35,'Fds Units'!DR:DR) -> 21 | K36: =SUMIF('Fds Units'!$BN:$BN,Summary!$A35,'Fds Units'!DS:DS) -> 15 | L36: =SUMIF('Fds Units'!$BQ:$BQ,Summary!$A35,'Fds Units'!DT:DT) -> 18 | M36: =SUMIF('Fds Units'!$BT:$BT,Summary!$A35,'Fds Units'!DU:DU) -> 22 | N36: =SUMIF('Fds Units'!$BW:$BW,Summary!$A35,'Fds Units'!DV:DV) -> 23 | O36: =SUMIF('Fds Units'!$BZ:$BZ,Summary!$A35,'Fds Units'!DW:DW) -> 28 | P36: =SUMIF('Fds Units'!$CC:$CC,Summary!$A35,'Fds Units'!DX:DX) -> 24 | Q36: =SUMIF('Fds Units'!$CF:$CF,Summary!$A35,'Fds Units'!DY:DY) -> 16 | R36: =SUMIF('Fds Units'!$CI:$CI,Summary!$A35,'Fds Units'!DZ:DZ) -> 17 | S36: =SUMIF('Fds Units'!$CL:$CL,Summary!$A35,'Fds Units'!EA:EA) -> 14 | T36: =SUMIF('Fds Units'!$CO:$CO,Summary!$A35,'Fds Units'!EB:EB) -> 8 | U36: =SUMIF('Fds Units'!$CR:$CR,Summary!$A35,'Fds Units'!EC:EC) -> 12 | V36: =SUMIF('Fds Units'!$CU:$CU,Summary!$A35,'Fds Units'!ED:ED) -> 7 | W36: =SUMIF('Fds Units'!$CX:$CX,Summary!$A35,'Fds Units'!EE:EE) -> 11 | X36: =SUMIF('Fds Units'!$DA:$DA,Summary!$A35,'Fds Units'!EF:EF) -> 9 | Y36: =SUMIF('Fds Units'!$DD:$DD,Summary!$A35,'Fds Units'!EG:EG) -> 11 | Z36: =SUMIF('Fds Units'!$DG:$DG,Summary!$A35,'Fds Units'!EH:EH) -> 4
B37: Days Under/(Over) | C37: =+C$11-C36 -> 0 | D37: =+D$11-D36 -> 0 | E37: =+E$11-E36 -> 0 | F37: =+F$11-F36 -> -2 | G37: =+G$11-G36 -> 0 | H37: =+H$11-H36 -> 0 | I37: =+I$11-I36 -> 0 | J37: =+J$11-J36 -> 4 | ... P37: =+P$11-P36 -> 0 | Q37: =+Q$8-Q36 -> 6 | R37: =+R$8-R36 -> 5 | S37: =+S$8-S36 -> 6 | T37: =+T$8-T36 -> 14 | U37: =+U$8-U36 -> 10 | V37: =+V$8-V36 -> 14 | W37: =+W$8-W36 -> 10 | X37: =+X$8-X36 -> 13 | ... Z37: =+Z$8-Z36 -> 17
B38: Retort Cycles Req'd | C38: =SUMIF('Fds Units'!$AP:$AP,Summary!$A35,'Fds Units'!EJ:EJ) -> 104 | D38: =SUMIF('Fds Units'!$AS:$AS,Summary!$A35,'Fds Units'!EK:EK) -> 82 | E38: =SUMIF('Fds Units'!$AV:$AV,Summary!$A35,'Fds Units'!EL:EL) -> 104 | F38: =SUMIF('Fds Units'!$AY:$AY,Summary!$A35,'Fds Units'!EM:EM) -> 128 | G38: =SUMIF('Fds Units'!$BB:$BB,Summary!$A35,'Fds Units'!EN:EN) -> 112 | H38: =SUMIF('Fds Units'!$BE:$BE,Summary!$A35,'Fds Units'!EO:EO) -> 116 | I38: =SUMIF('Fds Units'!$BH:$BH,Summary!$A35,'Fds Units'!EP:EP) -> 100 | J38: =SUMIF('Fds Units'!$BK:$BK,Summary!$A35,'Fds Units'!EQ:EQ) -> 84 | K38: =SUMIF('Fds Units'!$BN:$BN,Summary!$A35,'Fds Units'!ER:ER) -> 60 | L38: =SUMIF('Fds Units'!$BQ:$BQ,Summary!$A35,'Fds Units'!ES:ES) -> 184 | M38: =SUMIF('Fds Units'!$BT:$BT,Summary!$A35,'Fds Units'!ET:ET) -> 88 | N38: =SUMIF('Fds Units'!$BW:$BW,Summary!$A35,'Fds Units'!EU:EU) -> 92 | O38: =SUMIF('Fds Units'!$BZ:$BZ,Summary!$A35,'Fds Units'!EV:EV) -> 112 | P38: =SUMIF('Fds Units'!$CC:$CC,Summary!$A35,'Fds Units'!EW:EW) -> 96 | Q38: =SUMIF('Fds Units'!$CF:$CF,Summary!$A35,'Fds Units'!EX:EX) -> 64 | R38: =SUMIF('Fds Units'!$CI:$CI,Summary!$A35,'Fds Units'!EY:EY) -> 68 | S38: =SUMIF('Fds Units'!$CL:$CL,Summary!$A35,'Fds Units'!EZ:EZ) -> 56 | T38: =SUMIF('Fds Units'!$CO:$CO,Summary!$A35,'Fds Units'!FA:FA) -> 32 | U38: =SUMIF('Fds Units'!$CR:$CR,Summary!$A35,'Fds Units'!FB:FB) -> 48 | V38: =SUMIF('Fds Units'!$CU:$CU,Summary!$A35,'Fds Units'!FC:FC) -> 28 | W38: =SUMIF('Fds Units'!$CX:$CX,Summary!$A35,'Fds Units'!FD:FD) -> 44 | X38: =SUMIF('Fds Units'!$DA:$DA,Summary!$A35,'Fds Units'!FE:FE) -> 36 | Y38: =SUMIF('Fds Units'!$DD:$DD,Summary!$A35,'Fds Units'!FF:FF) -> 44 | Z38: =SUMIF('Fds Units'!$DG:$DG,Summary!$A35,'Fds Units'!FG:FG) -> 16
C39: =+C35/C$74 -> 0.17745035 | D39: =+D35/D$74 -> 0.19608393 | E39: =+E35/E$74 -> 0.17855599 | F39: =+F35/F$74 -> 0.20217451 | G39: =+G35/G$74 -> 0.20383053 | H39: =+H35/H$74 -> 0.209674 | I39: =+I35/I$74 -> 0.20885423 | J39: =+J35/J$74 -> 0.20760477 | ... Z39: =+Z35/Z$74 -> 0.050415669
A40: Y4N | B40: Volume | C40: =SUMIF('Fds Units'!$AP:$AP,Summary!$A40,'Fds Units'!B:B) -> 76344 | D40: =SUMIF('Fds Units'!$AS:$AS,Summary!$A40,'Fds Units'!C:C) -> 110886 | E40: =SUMIF('Fds Units'!$AV:$AV,Summary!$A40,'Fds Units'!D:D) -> 107892 | F40: =+Prophix!G188 -> 0 | G40: =SUMIF('Fds Units'!$BB:$BB,Summary!$A40,'Fds Units'!F:F) -> 275603 | H40: =SUMIF('Fds Units'!$BE:$BE,Summary!$A40,'Fds Units'!G:G) -> 903018 | I40: =SUMIF('Fds Units'!$BH:$BH,Summary!$A40,'Fds Units'!H:H) -> 500964 | J40: =SUMIF('Fds Units'!$BK:$BK,Summary!$A40,'Fds Units'!I:I) -> 95409 | K40: =SUMIF('Fds Units'!$BN:$BN,Summary!$A40,'Fds Units'!J:J) -> 0 | L40: =SUMIF('Fds Units'!$BQ:$BQ,Summary!$A40,'Fds Units'!K:K) -> 896 | M40: =SUMIF('Fds Units'!$BT:$BT,Summary!$A40,'Fds Units'!L:L)+SUMIF('Fds Units'!$BT:$BT,Summary!$A40,'Fds Units'!N:N) -> 0 | N40: =SUMIF('Fds Units'!$BW:$BW,Summary!$A40,'Fds Units'!R:R) -> 0 | O40: =SUMIF('Fds Units'!$BZ:$BZ,Summary!$A40,'Fds Units'!V:V) -> 0 | P40: =SUMIF('Fds Units'!$CC:$CC,Summary!$A40,'Fds Units'!Z:Z) -> 0 | Q40: =SUMIF('Fds Units'!$CF:$CF,Summary!$A40,'Fds Units'!AC:AC) -> 0 | R40: =SUMIF('Fds Units'!$CI:$CI,Summary!$A40,'Fds Units'!AF:AF) -> 0 | S40: =SUMIF('Fds Units'!$CL:$CL,Summary!$A40,'Fds Units'!AG:AG) -> 0 | T40: =SUMIF('Fds Units'!$CO:$CO,Summary!$A40,'Fds Units'!AH:AH) -> 0 | U40: =SUMIF('Fds Units'!$CR:$CR,Summary!$A40,'Fds Units'!AI:AI) -> 0 | V40: =SUMIF('Fds Units'!$CU:$CU,Summary!$A40,'Fds Units'!AJ:AJ) -> 0 | W40: =SUMIF('Fds Units'!$CX:$CX,Summary!$A40,'Fds Units'!AK:AK) -> 0 | X40: =SUMIF('Fds Units'!$DA:$DA,Summary!$A40,'Fds Units'!AL:AL) -> 0 | Y40: =SUMIF('Fds Units'!$DD:$DD,Summary!$A40,'Fds Units'!AM:AM) -> 0 | Z40: =SUMIF('Fds Units'!$DG:$DG,Summary!$A40,'Fds Units'!AN:AN) -> 0
B41: Days | C41: =SUMIF('Fds Units'!$AP:$AP,Summary!$A40,'Fds Units'!DK:DK) -> 3 | D41: =SUMIF('Fds Units'!$AS:$AS,Summary!$A40,'Fds Units'!DL:DL) -> 4 | E41: =SUMIF('Fds Units'!$AV:$AV,Summary!$A40,'Fds Units'!DM:DM) -> 4 | F41: 3 | G41: =SUMIF('Fds Units'!$BB:$BB,Summary!$A40,'Fds Units'!DO:DO) -> 7 | H41: =SUMIF('Fds Units'!$BE:$BE,Summary!$A40,'Fds Units'!DP:DP) -> 22 | I41: =SUMIF('Fds Units'!$BH:$BH,Summary!$A40,'Fds Units'!DQ:DQ) -> 11 | J41: =SUMIF('Fds Units'!$BK:$BK,Summary!$A40,'Fds Units'!DR:DR) -> 4 | K41: =SUMIF('Fds Units'!$BN:$BN,Summary!$A40,'Fds Units'!DS:DS) -> 0 | L41: =SUMIF('Fds Units'!$BQ:$BQ,Summary!$A40,'Fds Units'!DT:DT) -> 1 | M41: =SUMIF('Fds Units'!$BT:$BT,Summary!$A40,'Fds Units'!DU:DU) -> 0 | N41: =SUMIF('Fds Units'!$BW:$BW,Summary!$A40,'Fds Units'!DV:DV) -> 0 | O41: =SUMIF('Fds Units'!$BZ:$BZ,Summary!$A40,'Fds Units'!DW:DW) -> 0 | P41: =SUMIF('Fds Units'!$CC:$CC,Summary!$A40,'Fds Units'!DX:DX) -> 0 | Q41: =SUMIF('Fds Units'!$CF:$CF,Summary!$A40,'Fds Units'!DY:DY) -> 0 | R41: =SUMIF('Fds Units'!$CI:$CI,Summary!$A40,'Fds Units'!DZ:DZ) -> 0 | S41: =SUMIF('Fds Units'!$CL:$CL,Summary!$A40,'Fds Units'!EA:EA) -> 0 | T41: =SUMIF('Fds Units'!$CO:$CO,Summary!$A40,'Fds Units'!EB:EB) -> 0 | U41: =SUMIF('Fds Units'!$CR:$CR,Summary!$A40,'Fds Units'!EC:EC) -> 0 | V41: =SUMIF('Fds Units'!$CU:$CU,Summary!$A40,'Fds Units'!ED:ED) -> 0 | W41: =SUMIF('Fds Units'!$CX:$CX,Summary!$A40,'Fds Units'!EE:EE) -> 0 | X41: =SUMIF('Fds Units'!$DA:$DA,Summary!$A40,'Fds Units'!EF:EF) -> 0 | Y41: =SUMIF('Fds Units'!$DD:$DD,Summary!$A40,'Fds Units'!EG:EG) -> 0 | Z41: =SUMIF('Fds Units'!$DG:$DG,Summary!$A40,'Fds Units'!EH:EH) -> 0
...

Sheet Fds Units
A1: S&OP 2026 | B1: =EOMONTH(C1,-1) -> 45688 | C1: =EOMONTH(D1,-1) -> 45716 | D1: 45747 | E1: =EOMONTH(D1,1) -> 45777 | F1: =EOMONTH(E1,1) -> 45808 | G1: =EOMONTH(F1,1) -> 45838 | H1: =EOMONTH(G1,1) -> 45869 | I1: =EOMONTH(H1,1) -> 45900 | J1: =EOMONTH(I1,1) -> 45930 | K1: =EOMONTH(J1,1) -> 45961 | L1: =EOMONTH(K1,1) -> 45991 | M1: =EOMONTH(K1,1) -> 45991 | P1: =EOMONTH(M1,1) -> 46022 | Q1: =+P1 -> 46022 | U1: =EOMONTH(Q1,1) -> 46053 | Y1: =EOMONTH(U1,1) -> 46081 | AC1: =EOMONTH(Y1,1) -> 46112 | AF1: =EOMONTH(AC1,1) -> 46142 | AG1: =EOMONTH(AF1,1) -> 46173 | AH1: =EOMONTH(AG1,1) -> 46203 | AI1: =EOMONTH(AH1,1) -> 46234 | AJ1: =EOMONTH(AI1,1) -> 46265 | AK1: =EOMONTH(AJ1,1) -> 46295 | AL1: =EOMONTH(AK1,1) -> 46326 | AM1: =EOMONTH(AL1,1) -> 46356 | AN1: =EOMONTH(AM1,1) -> 46387 | AP1: =+B1 -> 45688 | AS1: =+C1 -> 45716 | AV1: =+D1 -> 45747 | AY1: =+E1 -> 45777 | BB1: =+F1 -> 45808 | BE1: =+EOMONTH(BB1,1) -> 45838 | BH1: July | BK1: Aug | BN1: Sept | BQ1: Oct | BT1: Nov | BW1: Dec | BZ1: Jan | CC1: Feb | CF1: Mar | CI1: Apr | CL1: May | CO1: June | CR1: July | CU1: August | CX1: Sept | DA1: Oct | DD1: Nov | DG1: Dec | DK1: =+EJ1 -> Jan | DL1: =+EK1 -> Feb | DM1: =+EL1 -> Mar | DN1: =+EM1 -> Apr | DO1: =+EN1 -> May | DP1: =+EO1 -> Jun | DQ1: =+EP1 -> Jul | DR1: =+EQ1 -> Aug | ... EB1: =+FA1 -> Jun | EC1: July | ED1: Aug | EE1: Sept | EF1: Oct | EG1: Nov | EH1: Dec | EJ1: Jan | EK1: Feb | EL1: Mar | EM1: Apr | EN1: May | EO1: Jun | EP1: Jul | EQ1: Aug | ER1: Sep | ES1: Oct | ET1: Nov | EU1: Dec | EV1: Jan | EW1: Feb | EX1: Mar | EY1: Apr | EZ1: May | FA1: Jun | FB1: =+EC1 -> July | FC1: =+ED1 -> Aug | FD1: =+EE1 -> Sept | FE1: =+EF1 -> Oct | FF1: =+EG1 -> Nov | FG1: =+EH1 -> Dec
A2: Foods | B2: Actuals | C2: Actuals | D2: Actuals | E2: Actuals | F2: Actuals | G2: Actuals | H2: Actuals | I2: Actuals | J2: Actuals | K2: Actuals | L2: Actuals | M2: Forecast | N2: Schedule | O2: Variance | P2: Demand (PO) | Q2: Forecast | R2: Schedule | S2: Actual Production | T2: Variance | U2: Pre Month Schedule | V2: Scheduled | W2: Customer Forecast | X2: Actuals | Y2: Pre Month Schedule | Z2: Scheduled | AA2: Actuals | AB2: Variance | AC2: Pre Month Schedule | AD2: Forecast | AE2: Scheduled | AF2: =+AD2 -> Forecast | AG2: =+AF2 -> Forecast | AH2: =+AG2 -> Forecast | AI2: =+AH2 -> Forecast | AJ2: =+AI2 -> Forecast | AK2: =+AJ2 -> Forecast | AL2: =+AK2 -> Forecast | AM2: =+AL2 -> Forecast | AN2: =+AM2 -> Forecast | AP2: Machine | AQ2: Throughput | AR2: Retorts | AS2: Machine | AT2: Throughput | AU2: Retorts | AV2: Machine | AW2: Throughput | AX2: Retorts | AY2: Machine | AZ2: Throughput | BA2: Retorts | BB2: Machine | BC2: Throughput | BD2: Retorts | BE2: Machine | BF2: Throughput | BG2: Retorts | BH2: Machine | BI2: Throughput | BJ2: Retorts | BK2: Machine | BL2: Throughput | BM2: Retorts | BN2: Machine | BO2: Throughput | BP2: Retorts | BQ2: Machine | BR2: Throughput | BS2: Retorts | BT2: Machine | BU2: Throughput | BV2: Retorts | BW2: Machine | BX2: Throughput | BY2: Retorts | BZ2: Machine | CA2: Throughput | CB2: Retorts | CC2: Machine | CD2: Throughput | CE2: Retorts | CF2: Machine | CG2: Throughput | CH2: Retorts | CI2: Machine | CJ2: Throughput | CK2: Retorts | CL2: Machine | CM2: Throughput | CN2: Retorts | CO2: Machine | CP2: Throughput | CQ2: Retorts | CR2: Machine | CS2: Throughput | CT2: Retorts | CU2: Machine | CV2: Throughput | CW2: Retorts | CX2: Machine | CY2: Throughput | CZ2: Retorts | DA2: Machine | DB2: Throughput | DC2: Retorts | DD2: Machine | DE2: Throughput | DF2: Retorts | DG2: Machine | DH2: Throughput | DI2: Retorts | DK2: =+B2 -> Actuals | DL2: =+C2 -> Actuals | DM2: =+D2 -> Actuals | DN2: =+E2 -> Actuals | DO2: =+F2 -> Actuals | DP2: =+G2 -> Actuals | DQ2: =+H2 -> Actuals | DR2: =+I2 -> Actuals | DS2: =+DR2 -> Actuals | DT2: =+N2 -> Schedule | DU2: =+R2 -> Schedule | DV2: =+U2 -> Pre Month Schedule | DW2: =+DV2 -> Pre Month Schedule | DX2: =+DW2 -> Pre Month Schedule | DY2: =+DX2 -> Pre Month Schedule | DZ2: =+DY2 -> Pre Month Schedule | EA2: =+DZ2 -> Pre Month Schedule | EB2: =+EA2 -> Pre Month Schedule | EC2: =+EB2 -> Pre Month Schedule | ED2: =+EC2 -> Pre Month Schedule | ... EH2: =+EG2 -> Pre Month Schedule | EJ2: =+DK2 -> Actuals | EK2: =+DL2 -> Actuals | EL2: =+DM2 -> Actuals | EM2: =+DN2 -> Actuals | EN2: =+DO2 -> Actuals | EO2: =+DP2 -> Actuals | EP2: =+DQ2 -> Actuals | EQ2: =+DR2 -> Actuals | ... EU2: =+DV2 -> Pre Month Schedule | EV2: =+EU2 -> Pre Month Schedule | EW2: =+EV2 -> Pre Month Schedule | EX2: =+EW2 -> Pre Month Schedule | EY2: =+EX2 -> Pre Month Schedule | EZ2: =+EY2 -> Pre Month Schedule | FA2: =+EZ2 -> Pre Month Schedule | FB2: =+FA2 -> Pre Month Schedule | FC2: =+FB2 -> Pre Month Schedule | ... FG2: =+FF2 -> Pre Month Schedule
A3: Government | B3: =SUM(B4:B16)-B4 -> 3317098 | C3: =SUM(C4:C16)-C4 -> 3306913 | D3: =SUM(D4:D16)-D4 -> 2436994 | E3: =SUM(E4:E16)-E4 -> 2922816 | F3: =SUM(F4:F16)-F4 -> 4385690 | G3: =SUM(G4:G16)-G4 -> 4539743 | H3: =SUM(H4:H16)-H4 -> 3175301 | I3: =SUM(I4:I16)-I4 -> 2322944 | ... S3: =SUM(S4:S16)-S4 -> 1979373 | T3: =S3-R3 -> -249427 | U3: =SUM(U4:U16)-U4 -> 2650000 | V3: =SUM(V4:V16)-V4 -> 2882200 | W3: =SUM(W4:W16)-W4 -> 1942902.2 | X3: =SUM(X4:X16)-X4 -> 2274125 | Y3: =SUM(Y4:Y16) -> 2514600 | Z3: =SUM(Z4:Z16) -> 2289300 | AA3: =SUM(AA4:AA16) -> 2171667 | AB3: =SUM(AB4:AB16) -> -117633 | AC3: =SUM(AC4:AC16) -> 1632375 | AD3: =SUM(AD4:AD16) -> 1633180 | AE3: =SUM(AE4:AE16) -> 1633180 | AF3: =SUM(AF4:AF16) -> 1760000 | ... AN3: =SUM(AN4:AN16) -> 418333 | FO3: Oct | FP3: Nov | FQ3: Dec
A4: MRE Base | B4: =SUMIF(Prophix!$Q:$Q,'Fds Units'!$A4,Prophix!D:D)-B8 -> 2001734 | C4: =SUMIF(Prophix!$Q:$Q,'Fds Units'!$A4,Prophix!E:E)-C8 -> 1659825 | D4: =SUMIF(Prophix!$Q:$Q,'Fds Units'!$A4,Prophix!F:F)-D8 -> 1876069 | E4: =SUMIF(Prophix!$Q:$Q,'Fds Units'!$A4,Prophix!G:G)-E8 -> 1866232 | F4: =SUMIF(Prophix!$Q:$Q,'Fds Units'!$A4,Prophix!H:H)-F8 -> 2534579 | G4: =SUMIF(Prophix!$Q:$Q,'Fds Units'!$A4,Prophix!I:I)-G8 -> 2606293 | H4: =SUMIF(Prophix!$Q:$Q,'Fds Units'!$A4,Prophix!J:J)-H8 -> 2504242 | I4: =SUMIF(Prophix!$Q:$Q,'Fds Units'!$A4,Prophix!K:K)-I8 -> 845959 | J4: =SUMIF(Prophix!$Q:$Q,'Fds Units'!$A4,Prophix!L:L)-J8 -> 1225444 | K4: =SUMIF(Prophix!$Q:$Q,'Fds Units'!$A4,Prophix!M:M)-K8 -> 1666391 | N4: =SUM(N5:N7) -> 1585000 | O4: =SUM(O5:O7) -> -225793 | P4: =+P5 -> 0 | Q4: =R4 -> 1261000 | R4: =SUM(R5:R7) -> 1261000 | S4: =SUM(S5:S7) -> 1251687 | T4: =S4-R4 -> -9313 | U4: 1915000 | V4: 2020000 | W4: 1369806.2 | X4: 1827130 | Y4: 1410000 | Z4: 1299000 | AA4: 1392780 | AB4: =AA4-Z4 -> 93780 | AC4: 1000000 | AD4: 1210000 | AE4: 1210000 | AF4: 1315000 | AG4: 1010000 | AH4: 400000 | AI4: 810000 | AJ4: 295000 | AK4: 820000 | AL4: 695000 | AM4: 810000 | AN4: 400000 | BZ4: Y3NS | CA4: 105000 | CB4: 4 | CC4: Y3NS | CD4: 105000 | CE4: 4 | CF4: Y3NS | CG4: 105000 | CH4: 4 | CI4: Y3NS | CJ4: 105000 | CK4: 4 | CL4: Y3NS | CM4: 105000 | CN4: 4 | CO4: Y3NS | CP4: 105000 | CQ4: 4 | CR4: Y3NS | CS4: 105000 | CT4: 4 | CU4: Y3NS | CV4: 105000 | CW4: 4 | CX4: Y3NS | CY4: 105000 | CZ4: 4 | DA4: Y3NS | DB4: 105000 | DC4: 4 | DD4: Y3NS | DE4: 105000 | DF4: 4 | DG4: Y3NS | DH4: 105000 | DI4: 4 | DK4: 0 | DL4: =IFERROR(ROUNDUP(+C4/$AT4,0),0) -> 0 | DM4: =IFERROR(ROUNDUP(+D4/$AW4,0),0) -> 0 | DN4: =IFERROR(ROUNDUP(+E4/$AZ4,0),0) -> 0 | DO4: =IFERROR(ROUNDUP(+F4/$BC4,0),0) -> 0 | DP4: =IFERROR(ROUNDUP(+G4/$BF4,0),0) -> 0 | DQ4: =IFERROR(ROUNDUP(+$H4/$BI4,0),0) -> 0 | DR4: =IFERROR(ROUNDUP(+I4/$BL4,0),0) -> 0 | DS4: =IFERROR(ROUNDUP(J4/BO4,0),0) -> 0 | DT4: =IFERROR(ROUNDUP(+K4/BR4,0),0) -> 0 | DU4: =IFERROR(ROUNDUP(+N4/BU4,0),0) -> 0 | DV4: =IFERROR(ROUNDUP(+R4/BX4,0),0) -> 0 | DW4: =IFERROR(ROUNDUP(+V4/CA4,0),0) -> 20 | DX4: =IFERROR(ROUNDUP(+Y4/CD4,0),0) -> 14 | DY4: =IFERROR(ROUNDUP(+AE4/CG4,0),0) -> 12 | DZ4: =IFERROR(ROUNDUP(+AF4/CJ4,0),0) -> 13 | EA4: =IFERROR(ROUNDUP(+AG4/CM4,0),0) -> 10 | EB4: =IFERROR(ROUNDUP(+AH4/CP4,0),0) -> 4 | EC4: =IFERROR(ROUNDUP(+AI4/CS4,0),0) -> 8 | ED4: =IFERROR(ROUNDUP(+AJ4/CV4,0),0) -> 3 | EE4: =IFERROR(ROUNDUP(+AK4/CY4,0),0) -> 8 | EF4: =IFERROR(ROUNDUP(+AL4/DB4,0),0) -> 7 | EG4: =IFERROR(ROUNDUP(+AM4/DE4,0),0) -> 8 | EH4: =IFERROR(ROUNDUP(+AN4/DH4,0),0) -> 4 | EJ4: =$AR4*DK4 -> 0 | EK4: =$AU4*DL4 -> 0 | EL4: =$AX4*DM4 -> 0 | EM4: =$BA4*DN4 -> 0 | EN4: =$BD4*DO4 -> 0 | EO4: =$BG4*DP4 -> 0 | EP4: =BJ4*DQ4 -> 0 | EQ4: =+BM4*DR4 -> 0 | ER4: =BP4*DS4 -> 0 | ES4: =+BS4*DT4 -> 0 | ET4: =+BV4*DU4 -> 0 | EU4: =+BY4*DV4 -> 0 | EV4: =+CB4*DW4 -> 80 | EW4: =+CE4*DX4 -> 56 | EX4: =+CH4*DY4 -> 48 | EY4: =+CK4*DZ4 -> 52 | EZ4: =+CN4*EA4 -> 40 | FA4: =+CQ4*EB4 -> 16 | FB4: =+CT4*EC4 -> 32 | FC4: =+CW4*ED4 -> 12 | FD4: =+CZ4*EE4 -> 32 | FE4: =+DC4*EF4 -> 28 | FF4: =+DF4*EG4 -> 32 | FG4: =+DI4*EH4 -> 16 | FO4: =+A4&BQ4 -> MRE Base | FP4: =+A4&BT4 -> MRE Base | FQ4: =+A4&BW4 -> MRE Base | FR4: MRE Base Total
A5: MRE Base | B5: =+B4 -> 2001734 | C5: =+C4 -> 1659825 | D5: =+D4 -> 1876069 | E5: =+E4 -> 1866232 | F5: =+F4-F6-F7 -> 1962049 | G5: =+G4-G6-G7 -> 1703275 | H5: =+H4-H6-H7 -> 2003278 | I5: =+I4-I6-I7 -> 845959 | J5: =+J4-J6-J7 -> 1225444 | K5: =+K4-K6-K7 -> 1665495 | L5: 1359207 | M5: =-'[1]RNC by SKU'!$U$77+20000 -> 20000 | N5: 1585000 | O5: =L5-N5 -> -225793 | Q5: =R5 -> 1261000 | R5: 1261000 | S5: 1251687 | T5: =+R5-Q5 -> 0 | U5: 1915000 | V5: 2020000 | W5: =W4 -> 1369806.2 | X5: 1827130 | Y5: 0 | AB5: 0 | AP5: Y3NS | AQ5: 105000 | AR5: 4 | AS5: Y3NS | AT5: 95000 | AU5: 3 | AV5: Y3NS | AW5: 88000 | AX5: 4 | AY5: Y3NS | AZ5: =+E5/21 -> 88868.19 | BA5: 4 | BB5: Y3NS | BC5: 100000 | BD5: 4 | BE5: Y3NS | BF5: =+G5/18 -> 94626.389 | BG5: 4 | BH5: Y3NS | BI5: =+H5/22 -> 91058.091 | BJ5: 4 | BK5: Y3NS | BL5: =+I5/13 -> 65073.769 | BM5: 4 | BN5: Y3NS | BO5: =+J5/14 -> 87531.714 | BP5: 4 | BQ5: Y3NS | BR5: =+N5/8 -> 198125 | BS5: 4 | BT5: Y3NS | BU5: =+R5/20 -> 63050 | BV5: 4 | BW5: Y3NS | BX5: 105000 | BY5: 4 | DK5: 22 | DL5: =IFERROR(ROUNDUP(+C5/$AT5,0),0) -> 18 | DM5: =IFERROR(ROUNDUP(+D5/$AW5,0),0) -> 22 | DN5: 20 | DO5: =IFERROR(ROUNDUP(+F5/$BC5,0),0) -> 20 | DP5: =IFERROR(ROUNDUP(+G5/$BF5,0),0) -> 18 | DQ5: =IFERROR(ROUNDUP(+$H5/$BI5,0),0) -> 22 | DR5: =IFERROR(ROUNDUP(+I5/$BL5,0),0) -> 13 | DS5: =IFERROR(ROUNDUP(J5/BO5,0),0) -> 14 | DT5: =IFERROR(ROUNDUP(+K5/BR5,0),0)-9 -> 0 | DU5: 15 | DV5: 14 | DW5: =IFERROR(ROUNDUP(+U5/CA5,0),0) -> 0 | DX5: =IFERROR(ROUNDUP(+Y5/CD5,0),0) -> 0 | DY5: =IFERROR(ROUNDUP(+AE5/CG5,0),0) -> 0 | DZ5: =IFERROR(ROUNDUP(+AF5/CJ5,0),0) -> 0 | EA5: =IFERROR(ROUNDUP(+AG5/CM5,0),0) -> 0 | EB5: =IFERROR(ROUNDUP(+AH5/CP5,0),0) -> 0 | EC5: =IFERROR(ROUNDUP(+AI5/CS5,0),0) -> 0 | ED5: =IFERROR(ROUNDUP(+AJ5/CV5,0),0) -> 0 | EE5: =IFERROR(ROUNDUP(+AK5/CY5,0),0) -> 0 | EF5: =IFERROR(ROUNDUP(+AL5/DB5,0),0) -> 0 | EG5: =IFERROR(ROUNDUP(+AM5/DE5,0),0) -> 0 | EH5: =IFERROR(ROUNDUP(+AN5/DH5,0),0) -> 0 | EJ5: =$AR5*DK5 -> 88 | EK5: =$AU5*DL5 -> 54 | EL5: =$AX5*DM5 -> 88 | EM5: =$BA5*DN5 -> 80 | EN5: =$BD5*DO5 -> 80 | EO5: =$BG5*DP5 -> 72 | EP5: =BJ5*DQ5 -> 88 | EQ5: =+BM5*DR5 -> 52 | ER5: =BP5*DS5 -> 56 | ES5: =+BS5*DT5 -> 0 | ET5: =+BV5*DU5 -> 60 | EU5: =+BY5*DV5 -> 56 | EV5: =+CB5*DW5 -> 0 | EW5: =+CE5*DX5 -> 0 | EX5: =+CH5*DY5 -> 0 | EY5: =+CK5*DZ5 -> 0 | EZ5: =+CN5*EA5 -> 0 | FA5: =+CQ5*EB5 -> 0 | FB5: =+CT5*EC5 -> 0 | FC5: =+CW5*ED5 -> 0 | FD5: =+CZ5*EE5 -> 0 | FE5: =+DC5*EF5 -> 0 | FF5: =+DF5*EG5 -> 0 | FG5: =+DI5*EH5 -> 0 | FO5: =+A5&BQ5 -> MRE BaseY3NS | FP5: =+A5&BT5 -> MRE BaseY3NS | FQ5: =+A5&BW5 -> MRE BaseY3NS | FR5: MRE Base Total
A6: MRE Base | F6: 296927 | N6: 0 | O6: =+N6-M6 -> 0 | R6: =SUMIF(Schedule!$R:$R,$FQ6,Schedule!Q:Q) -> 0 | Y6: 0 | AB6: 0 | BB6: Y4S/Y5 | BC6: 75000 | BD6: 3 | BE6: Y4S/Y5 | BF6: 75000 | BG6: 3 | BH6: Y4S/Y5 | BI6: 75000 | BJ6: 3 | BK6: Y4S/Y5 | BL6: 75000 | BM6: 3 | BN6: Y4S/Y5 | BO6: 75000 | BP6: 3 | BQ6: Y4S/Y5 | BR6: 75000 | BS6: 3 | BT6: Y4S/Y5 | BU6: 75000 | BV6: 3 | BZ6: =+BW6 -> 0 | CA6: =+BX6 -> 0 | CB6: =+BY6 -> 0 | CC6: =+BZ6 -> 0 | CD6: =+CA6 -> 0 | CE6: =+CB6 -> 0 | CF6: =+CC6 -> 0 | CG6: =+CD6 -> 0 | ... DI6: =+DF6 -> 0 | DK6: =IFERROR(ROUNDUP(+B6/$AQ6,0),0) -> 0 | DL6: =IFERROR(ROUNDUP(+C6/$AT6,0),0) -> 0 | DM6: =IFERROR(ROUNDUP(+D6/$AW6,0),0) -> 0 | DN6: =IFERROR(ROUNDUP(+E6/$AZ6,0),0) -> 0 | DO6: =IFERROR(ROUNDUP(+F6/$BC6,0),0) -> 4 | DP6: =IFERROR(ROUNDUP(+G6/$BF6,0),0) -> 0 | DQ6: =IFERROR(ROUNDUP(+$H6/$BI6,0),0) -> 0 | DR6: =IFERROR(ROUNDUP(+I6/$BL6,0),0) -> 0 | DS6: =IFERROR(ROUNDUP(J6/BO6,0),0) -> 0 | DT6: =IFERROR(ROUNDUP(+K6/BR6,0),0) -> 0 | DU6: =IFERROR(ROUNDUP(+N6/BU6,0),0) -> 0 | DV6: =IFERROR(ROUNDUP(+R6/BX6,0),0) -> 0 | DW6: =IFERROR(ROUNDUP(+U6/CA6,0),0) -> 0 | DX6: =IFERROR(ROUNDUP(+Y6/CD6,0),0) -> 0 | DY6: =IFERROR(ROUNDUP(+AE6/CG6,0),0) -> 0 | DZ6: =IFERROR(ROUNDUP(+AF6/CJ6,0),0) -> 0 | EA6: =IFERROR(ROUNDUP(+AG6/CM6,0),0) -> 0 | EB6: =IFERROR(ROUNDUP(+AH6/CP6,0),0) -> 0 | EC6: =IFERROR(ROUNDUP(+AI6/CS6,0),0) -> 0 | ED6: =IFERROR(ROUNDUP(+AJ6/CV6,0),0) -> 0 | EE6: =IFERROR(ROUNDUP(+AK6/CY6,0),0) -> 0 | EF6: =IFERROR(ROUNDUP(+AL6/DB6,0),0) -> 0 | EG6: =IFERROR(ROUNDUP(+AM6/DE6,0),0) -> 0 | EH6: =IFERROR(ROUNDUP(+AN6/DH6,0),0) -> 0 | EJ6: =$AR6*DK6 -> 0 | EK6: =$AU6*DL6 -> 0 | EL6: =$AX6*DM6 -> 0 | EM6: =$BA6*DN6 -> 0 | EN6: =$BD6*DO6 -> 12 | EO6: =$BG6*DP6 -> 0 | EP6: =BJ6*DQ6 -> 0 | EQ6: =+BM6*DR6 -> 0 | ER6: =BP6*DS6 -> 0 | ES6: =+BS6*DT6 -> 0 | ET6: =+BV6*DU6 -> 0 | EU6: =+BY6*DV6 -> 0 | EV6: =+CB6*DW6 -> 0 | EW6: =+CE6*DX6 -> 0 | EX6: =+CH6*DY6 -> 0 | EY6: =+CK6*DZ6 -> 0 | EZ6: =+CN6*EA6 -> 0 | FA6: =+CQ6*EB6 -> 0 | FB6: =+CT6*EC6 -> 0 | FC6: =+CW6*ED6 -> 0 | FD6: =+CZ6*EE6 -> 0 | FE6: =+DC6*EF6 -> 0 | FF6: =+DF6*EG6 -> 0 | FG6: =+DI6*EH6 -> 0 | FO6: =+A6&BQ6 -> MRE BaseY4S/Y5 | FP6: =+A6&BT6 -> MRE BaseY4S/Y5 | FQ6: =+A6&BW6 -> MRE Base | FR6: MRE Base Total
A7: MRE Base | F7: 275603 | G7: 903018 | H7: 500964 | K7: 896 | M7: 600 | N7: 0 | O7: =L7-N7 -> 0 | R7: =SUMIF(Schedule!$R:$R,$FQ7,Schedule!Q:Q) -> 0 | Y7: 0 | AB7: 0 | BB7: Y4N | BC7: 45000 | BD7: 3 | BE7: Y4N | BF7: =+G7/22 -> 41046.273 | BG7: 3 | BH7: Y4N | BI7: =+H7/11 -> 45542.182 | BJ7: 3 | BK7: Y4N | BL7: 50000 | BM7: 3 | BN7: Y4N | BO7: 50000 | BP7: 3 | BQ7: Y4N | BR7: 50000 | BS7: 3 | BT7: Y4N | BU7: 50000 | BV7: 3 | BZ7: =+BW7 -> 0 | CA7: =+BX7 -> 0 | CB7: =+BY7 -> 0 | CC7: =+BZ7 -> 0 | CD7: =+CA7 -> 0 | CE7: =+CB7 -> 0 | CF7: =+CC7 -> 0 | CG7: =+CD7 -> 0 | ... DI7: =+DF7 -> 0 | DK7: =IFERROR(ROUNDUP(+B7/$AQ7,0),0) -> 0 | DL7: =IFERROR(ROUNDUP(+C7/$AT7,0),0) -> 0 | DM7: =IFERROR(ROUNDUP(+D7/$AW7,0),0) -> 0 | DN7: =IFERROR(ROUNDUP(+E7/$AZ7,0),0) -> 0 | DO7: =IFERROR(ROUNDUP(+F7/$BC7,0),0) -> 7 | DP7: =IFERROR(ROUNDUP(+G7/$BF7,0),0) -> 22 | DQ7: =IFERROR(ROUNDUP(+$H7/$BI7,0),0) -> 11 | DR7: =IFERROR(ROUNDUP(+I7/$BL7,0),0) -> 0 | DS7: =IFERROR(ROUNDUP(J7/BO7,0),0) -> 0 | DT7: =IFERROR(ROUNDUP(+K7/BR7,0),0) -> 1 | DU7: =IFERROR(ROUNDUP(+N7/BU7,0),0) -> 0 | DV7: =IFERROR(ROUNDUP(+R7/BX7,0),0) -> 0 | DW7: =IFERROR(ROUNDUP(+U7/CA7,0),0) -> 0 | DX7: =IFERROR(ROUNDUP(+Y7/CD7,0),0) -> 0 | DY7: =IFERROR(ROUNDUP(+AE7/CG7,0),0) -> 0 | DZ7: =IFERROR(ROUNDUP(+AF7/CJ7,0),0) -> 0 | EA7: =IFERROR(ROUNDUP(+AG7/CM7,0),0) -> 0 | EB7: =IFERROR(ROUNDUP(+AH7/CP7,0),0) -> 0 | EC7: =IFERROR(ROUNDUP(+AI7/CS7,0),0) -> 0 | ED7: =IFERROR(ROUNDUP(+AJ7/CV7,0),0) -> 0 | EE7: =IFERROR(ROUNDUP(+AK7/CY7,0),0) -> 0 | EF7: =IFERROR(ROUNDUP(+AL7/DB7,0),0) -> 0 | EG7: =IFERROR(ROUNDUP(+AM7/DE7,0),0) -> 0 | EH7: =IFERROR(ROUNDUP(+AN7/DH7,0),0) -> 0 | EJ7: =$AR7*DK7 -> 0 | EK7: =$AU7*DL7 -> 0 | EL7: =$AX7*DM7 -> 0 | EM7: =$BA7*DN7 -> 0 | EN7: =$BD7*DO7 -> 21 | EO7: =$BG7*DP7 -> 66 | EP7: =BJ7*DQ7 -> 33 | EQ7: =+BM7*DR7 -> 0 | ER7: =BP7*DS7 -> 0 | ES7: =+BS7*DT7 -> 3 | ET7: =+BV7*DU7 -> 0 | EU7: =+BY7*DV7 -> 0 | EV7: =+CB7*DW7 -> 0 | EW7: =+CE7*DX7 -> 0 | EX7: =+CH7*DY7 -> 0 | EY7: =+CK7*DZ7 -> 0 | EZ7: =+CN7*EA7 -> 0 | FA7: =+CQ7*EB7 -> 0 | FB7: =+CT7*EC7 -> 0 | FC7: =+CW7*ED7 -> 0 | FD7: =+CZ7*EE7 -> 0 | FE7: =+DC7*EF7 -> 0 | FF7: =+DF7*EG7 -> 0 | FG7: =+DI7*EH7 -> 0 | FO7: =+A7&BQ7 -> MRE BaseY4N | FP7: =+A7&BT7 -> MRE BaseY4N | FQ7: =+A7&BW7 -> MRE Base | FR7: MRE Base Total
A8: MRE Placeable | B8: =SUMIF(Prophix!$Q:$Q,'Fds Units'!$A8,Prophix!D:D) -> 127554 | C8: =SUMIF(Prophix!$Q:$Q,'Fds Units'!$A8,Prophix!E:E) -> 85061 | D8: =SUMIF(Prophix!$Q:$Q,'Fds Units'!$A8,Prophix!F:F) -> 138202 | E8: =SUMIF(Prophix!$Q:$Q,'Fds Units'!$A8,Prophix!G:G) -> 208528 | F8: =SUMIF(Prophix!$Q:$Q,'Fds Units'!$A8,Prophix!H:H) -> 207735 | G8: =SUMIF(Prophix!$Q:$Q,'Fds Units'!$A8,Prophix!I:I) -> 228150 | H8: =SUMIF(Prophix!$Q:$Q,'Fds Units'!$A8,Prophix!J:J) -> 219156 | I8: =SUMIF(Prophix!$Q:$Q,'Fds Units'!$A8,Prophix!K:K) -> 141173 | J8: =SUMIF(Prophix!$Q:$Q,'Fds Units'!$A8,Prophix!L:L) -> 142731 | K8: =SUMIF(Prophix!$Q:$Q,'Fds Units'!$A8,Prophix!M:M) -> 24055 | M8: 500 | N8: 0 | O8: =L8-N8 -> 0 | Q8: =+P8 -> 0 | R8: =SUMIF(Schedule!$R:$R,$FQ8,Schedule!Q:Q) -> 0 | T8: =+R8-Q8 -> 0 | U8: 0 | W8: 0 | X8: =+W8-U8 -> 0 | Y8: 0 | AB8: =AA8-Z8 -> 0 | AC8: 0 | AD8: 0 | AE8: 0 | AP8: V3 | AQ8: 50000 | AR8: 2 | AS8: V3 | AT8: 35000 | AU8: 2 | AV8: V3 | AW8: 45000 | AX8: 2 | AY8: V3 | AZ8: 45000 | BA8: 2 | BB8: V3 | BC8: 47000 | BD8: 2 | BE8: V3 | BF8: =+G8/5 -> 45630 | BG8: 2 | BH8: V3 | BI8: =+H8/6 -> 36526 | BJ8: 2 | BK8: V3 | BL8: 52500 | BM8: 2 | BN8: V3 | BO8: 52500 | BP8: 2 | BQ8: V3 | BR8: 52500 | BS8: 2 | BT8: V3 | BU8: 5500 | BV8: 2 | BW8: V3 | BX8: 50000 | BY8: 2 | BZ8: =+BW8 -> V3 | CA8: 0 | CB8: =+BY8 -> 2 | CC8: =+BZ8 -> V3 | CD8: =+CA8 -> 0 | CE8: =+CB8 -> 2 | CF8: =+CC8 -> V3 | CG8: =+CD8 -> 0 | CH8: =+CE8 -> 2 | CI8: =+CF8 -> V3 | ... DI8: =+DF8 -> 2 | DK8: =IFERROR(ROUNDUP(+B8/$AQ8,0),0) -> 3 | DL8: =IFERROR(ROUNDUP(+C8/$AT8,0),0) -> 3 | DM8: =IFERROR(ROUNDUP(+D8/$AW8,0),0) -> 4 | DN8: =IFERROR(ROUNDUP(+E8/$AZ8,0),0) -> 5 | DO8: =IFERROR(ROUNDUP(+F8/$BC8,0),0) -> 5 | DP8: =IFERROR(ROUNDUP(+G8/$BF8,0),0) -> 5 | DQ8: =IFERROR(ROUNDUP(+$H8/$BI8,0),0) -> 6 | DR8: =IFERROR(ROUNDUP(+I8/$BL8,0),0) -> 3 | DS8: =IFERROR(ROUNDUP(J8/BO8,0),0) -> 3 | DT8: =IFERROR(ROUNDUP(+K8/BR8,0),0) -> 1 | DU8: =IFERROR(ROUNDUP(+N8/BU8,0),0) -> 0 | DV8: =IFERROR(ROUNDUP(+R8/BX8,0),0) -> 0 | DW8: =IFERROR(ROUNDUP(+V8/CA8,0),0) -> 0 | DX8: =IFERROR(ROUNDUP(+Y8/CD8,0),0) -> 0 | DY8: =IFERROR(ROUNDUP(+AE8/CG8,0),0) -> 0 | DZ8: =IFERROR(ROUNDUP(+AF8/CJ8,0),0) -> 0 | EA8: =IFERROR(ROUNDUP(+AG8/CM8,0),0) -> 0 | EB8: =IFERROR(ROUNDUP(+AH8/CP8,0),0) -> 0 | EC8: =IFERROR(ROUNDUP(+AI8/CS8,0),0) -> 0 | ED8: =IFERROR(ROUNDUP(+AJ8/CV8,0),0) -> 0 | EE8: =IFERROR(ROUNDUP(+AK8/CY8,0),0) -> 0 | EF8: =IFERROR(ROUNDUP(+AL8/DB8,0),0) -> 0 | EG8: =IFERROR(ROUNDUP(+AM8/DE8,0),0) -> 0 | EH8: =IFERROR(ROUNDUP(+AN8/DH8,0),0) -> 0 | EJ8: =$AR8*DK8 -> 6 | EK8: =$AU8*DL8 -> 6 | EL8: =$AX8*DM8 -> 8 | EM8: =$BA8*DN8 -> 10 | EN8: =$BD8*DO8 -> 10 | EO8: =$BG8*DP8 -> 10 | EP8: =BJ8*DQ8 -> 12 | EQ8: =+BM8*DR8 -> 6 | ER8: =BP8*DS8 -> 6 | ES8: =+BS8*DT8 -> 2 | ET8: =+BV8*DU8 -> 0 | EU8: =+BY8*DV8 -> 0 | EV8: =+CB8*DW8 -> 0 | EW8: =+CE8*DX8 -> 0 | EX8: =+CH8*DY8 -> 0 | EY8: =+CK8*DZ8 -> 0 | EZ8: =+CN8*EA8 -> 0 | FA8: =+CQ8*EB8 -> 0 | FB8: =+CT8*EC8 -> 0 | FC8: =+CW8*ED8 -> 0 | FD8: =+CZ8*EE8 -> 0 | FE8: =+DC8*EF8 -> 0 | FF8: =+DF8*EG8 -> 0 | FG8: =+DI8*EH8 -> 0 | FO8: =+A8&BQ8 -> MRE PlaceableV3 | FP8: =+A8&BT8 -> MRE PlaceableV3 | FQ8: =+A8&BW8 -> MRE PlaceableV3 | FR8: MRE BaseV3
A9: RNC Fruit | B9: =SUMIF(Prophix!$Q:$Q,'Fds Units'!$A9,Prophix!D:D) -> 378535 | C9: =SUMIF(Prophix!$Q:$Q,'Fds Units'!$A9,Prophix!E:E) -> 691107 | D9: =SUMIF(Prophix!$Q:$Q,'Fds Units'!$A9,Prophix!F:F) -> 422723 | E9: =SUMIF(Prophix!$Q:$Q,'Fds Units'!$A9,Prophix!G:G) -> 626418 | F9: =SUMIF(Prophix!$Q:$Q,'Fds Units'!$A9,Prophix!H:H) -> 888962 | G9: =SUMIF(Prophix!$Q:$Q,'Fds Units'!$A9,Prophix!I:I) -> 1239340 | H9: =SUMIF(Prophix!$Q:$Q,'Fds Units'!$A9,Prophix!J:J) -> 351085 | I9: =SUMIF(Prophix!$Q:$Q,'Fds Units'!$A9,Prophix!K:K) -> 432200 | J9: =SUMIF(Prophix!$Q:$Q,'Fds Units'!$A9,Prophix!L:L) -> 95006 | K9: =SUMIF(Prophix!$Q:$Q,'Fds Units'!$A9,Prophix!M:M) -> 216003 | L9: 421730 | M9: =-'[1]RNC by SKU'!$U$81 -> 0 | N9: 420000 | O9: =L9-N9 -> 1730 | Q9: =R9 -> 945000 | R9: 945000 | S9: 707877 | T9: =S9-R9 -> -237123 | U9: 735000 | V9: 840000 | W9: 573096 | X9: 426202 | Y9: 1050000 | Z9: 938000 | AA9: 728636 | AB9: =AA9-Z9 -> -209364 | AC9: 630000 | AD9: 420000 | AE9: 420000 | AF9: 420000 | AG9: 420000 | AH9: 420000 | AI9: 105000 | AJ9: 420000 | AK9: 315000 | AL9: 210000 | AM9: 315000 | AN9: 0 | AP9: Y3NS | AQ9: 103000 | AR9: 4 | AS9: Y3NS | AT9: 105000 | AU9: 4 | AV9: Y3NS | AW9: 110000 | AX9: 4 | AY9: Y3NS | AZ9: 105000 | BA9: 4 | BB9: Y3NS | BC9: 115000 | BD9: 4 | BE9: Y3NS | BF9: =+G9/11 -> 112667.27 | BG9: 4 | BH9: Y3NS | BI9: =+H9/3 -> 117028.33 | BJ9: 4 | BK9: Y3NS | BL9: =+I9/4 -> 108050 | BM9: 4 | BN9: Y3NS | BO9: 105000 | BP9: 4 | BQ9: Y3NS | BR9: 105000 | BS9: 4 | BT9: Y3NS | BU9: 105000 | BV9: 4 | BW9: Y3NS | BX9: 105000 | BY9: 4 | BZ9: =+BW9 -> Y3NS | CA9: =+BX9 -> 105000 | CB9: =+BY9 -> 4 | CC9: =+BZ9 -> Y3NS | CD9: =+CA9 -> 105000 | CE9: =+CB9 -> 4 | CF9: =+CC9 -> Y3NS | CG9: =+CD9 -> 105000 | ... DI9: =+DF9 -> 4 | DK9: =IFERROR(ROUNDUP(+B9/$AQ9,0),0) -> 4 | DL9: =IFERROR(ROUNDUP(+C9/$AT9,0),0) -> 7 | DM9: =IFERROR(ROUNDUP(+D9/$AW9,0),0) -> 4 | DN9: =IFERROR(ROUNDUP(+E9/$AZ9,0),0) -> 6 | DO9: =IFERROR(ROUNDUP(+F9/$BC9,0),0) -> 8 | DP9: =IFERROR(ROUNDUP(+G9/$BF9,0),0) -> 11 | DQ9: =IFERROR(ROUNDUP(+$H9/$BI9,0),0) -> 3 | DR9: =IFERROR(ROUNDUP(+I9/$BL9,0),0) -> 4 | DS9: =IFERROR(ROUNDUP(J9/BO9,0),0) -> 1 | DT9: =IFERROR(ROUNDUP(+K9/BR9,0),0)-1 -> 2 | DU9: 4 | DV9: =IFERROR(ROUNDUP(+R9/BX9,0),0) -> 9 | DW9: =IFERROR(ROUNDUP(+V9/CA9,0),0) -> 8 | DX9: =IFERROR(ROUNDUP(+Y9/CD9,0),0) -> 10 | DY9: =IFERROR(ROUNDUP(+AE9/CG9,0),0) -> 4 | DZ9: =IFERROR(ROUNDUP(+AF9/CJ9,0),0) -> 4 | EA9: =IFERROR(ROUNDUP(+AG9/CM9,0),0) -> 4 | EB9: =IFERROR(ROUNDUP(+AH9/CP9,0),0) -> 4 | EC9: =IFERROR(ROUNDUP(+AI9/CS9,0),0) -> 1 | ED9: =IFERROR(ROUNDUP(+AJ9/CV9,0),0) -> 4 | EE9: =IFERROR(ROUNDUP(+AK9/CY9,0),0) -> 3 | EF9: =IFERROR(ROUNDUP(+AL9/DB9,0),0) -> 2 | EG9: =IFERROR(ROUNDUP(+AM9/DE9,0),0) -> 3 | EH9: =IFERROR(ROUNDUP(+AN9/DH9,0),0) -> 0 | EJ9: =$AR9*DK9 -> 16 | EK9: =$AU9*DL9 -> 28 | EL9: =$AX9*DM9 -> 16 | EM9: =$BA9*DN9 -> 24 | EN9: =$BD9*DO9 -> 32 | EO9: =$BG9*DP9 -> 44 | EP9: =BJ9*DQ9 -> 12 | EQ9: =+BM9*DR9 -> 16 | ER9: =BP9*DS9 -> 4 | ES9: =+BS9*DT9 -> 8 | ET9: =+BV9*DU9 -> 16 | EU9: =+BY9*DV9 -> 36 | EV9: =+CB9*DW9 -> 32 | EW9: =+CE9*DX9 -> 40 | EX9: =+CH9*DY9 -> 16 | EY9: =+CK9*DZ9 -> 16 | EZ9: =+CN9*EA9 -> 16 | FA9: =+CQ9*EB9 -> 16 | FB9: =+CT9*EC9 -> 4 | FC9: =+CW9*ED9 -> 16 | FD9: =+CZ9*EE9 -> 12 | FE9: =+DC9*EF9 -> 8 | FF9: =+DF9*EG9 -> 12 | FG9: =+DI9*EH9 -> 0 | FO9: =+A9&BQ9 -> RNC FruitY3NS | FP9: =+A9&BT9 -> RNC FruitY3NS | FQ9: =+A9&BW9 -> RNC FruitY3NS | FR9: RNC Fruit Total
